Workbook

Sheet Linhas Rápidas
A2: LINHA 10 - SHAMPOO E CONDICIONADOR (8 SH E 4 COND) | R2: LINHA 10 - SHAMPOO E CONDICIONADOR
A3: LINHA | B3: Nº ORDEM | C3: LOTE | D3: QTD (KG) | E3: PROGRAMADO | F3: REALIZADO | G3: CÓDIGO | H3: DESCRIÇÃO S.A. | I3: DATA CONGELADA | J3: DATA ATUALIZADA | K3: TB | L3: TC | M3: TA | N3: SAP | O3: STATUS | P3: FRASCOS | R3: CÓDIGO P.A. | S3: DESCRIÇÃO P.A. | T3: Nº ORDEM | U3: REALIZADO | V3: DATA SAP | W3: QTD (CXS) | X3: QTD (UND)
A4: 10 | B4: 1961282 | C4: T26D1443 | D4: 9500 | E4: =_xlfn.XLOOKUP(B4,COHVPI!A:A,COHVPI!E:E,0,0,1) -> 0 | F4: =_xlfn.XLOOKUP(B4,COHVPI!A:A,COHVPI!F:F) -> #N/A | G4: 466337 | H4: SA MONANGE QUIMICA SH T | I4: 46150 | J4: 46149 | N4: =_xlfn.XLOOKUP('Linhas Rápidas'!B4,COHVPI!A:A,COHVPI!I:I) -> #N/A | O4: - | P4: OK | R4: 24043-2 | S4: MONANGE SH REPARACAO POS QUI 12X325ML | T4: 1962552 | U4: =_xlfn.XLOOKUP(T4,COHVPI!A:A,COHVPI!F:F) -> 8260 | V4: =_xlfn.XLOOKUP(T4,COHVPI!A:A,COHVPI!I:I) -> 46150 | W4: =X4/12 -> 9600 | X4: 115200 | AD4: =VLOOKUP(B4,COHVPI!A:N,14,0) -> #N/A | AE4: =VLOOKUP(B4,COHVPI!A:E,5,0) -> #N/A | AF4: =AE4-D4 -> #N/A
A5: 10 | B5: 1961283 | C5: T26D1444 | D5: 9500 | E5: =_xlfn.XLOOKUP(B5,COHVPI!A:A,COHVPI!E:E,0,0,1) -> 0 | F5: =_xlfn.XLOOKUP(B5,COHVPI!A:A,COHVPI!F:F) -> #N/A | G5: 466337 | H5: SA MONANGE QUIMICA SH T | I5: 46150 | J5: 46149 | N5: =_xlfn.XLOOKUP('Linhas Rápidas'!B5,COHVPI!A:A,COHVPI!I:I) -> #N/A | O5: - | P5: OK | AD5: =VLOOKUP(B5,COHVPI!A:N,14,0) -> #N/A | AE5: =VLOOKUP(B5,COHVPI!A:E,5,0) -> #N/A | AF5: =AE5-D5 -> #N/A
A6: 10 | B6: 1961284 | C6: T26D1445 | D6: 9500 | E6: =_xlfn.XLOOKUP(B6,COHVPI!A:A,COHVPI!E:E,0,0,1) -> 0 | F6: =_xlfn.XLOOKUP(B6,COHVPI!A:A,COHVPI!F:F) -> #N/A | G6: 466337 | H6: SA MONANGE QUIMICA SH T | I6: 46150 | J6: 46150 | N6: =_xlfn.XLOOKUP('Linhas Rápidas'!B6,COHVPI!A:A,COHVPI!I:I) -> #N/A | O6: - | P6: OK | U6: =_xlfn.XLOOKUP(T6,COHVPI!A:A,COHVPI!F:F) -> #N/A | AD6: =VLOOKUP(B6,COHVPI!A:N,14,0) -> #N/A | AE6: =VLOOKUP(B6,COHVPI!A:E,5,0) -> #N/A | AF6: =AE6-D6 -> #N/A
A7: 10 | B7: 1961285 | C7: T26D1446 | D7: 9500 | E7: =_xlfn.XLOOKUP(B7,COHVPI!A:A,COHVPI!E:E,0,0,1) -> 0 | F7: =_xlfn.XLOOKUP(B7,COHVPI!A:A,COHVPI!F:F) -> #N/A | G7: 466337 | H7: SA MONANGE QUIMICA SH T | I7: 46150 | J7: 46150 | N7: =_xlfn.XLOOKUP('Linhas Rápidas'!B7,COHVPI!A:A,COHVPI!I:I) -> #N/A | O7: - | P7: OK | AD7: =VLOOKUP(B7,COHVPI!A:N,14,0) -> #N/A | AE7: =VLOOKUP(B7,COHVPI!A:E,5,0) -> #N/A | AF7: =AE7-D7 -> #N/A
A8: 10 | B8: 1961358 | C8: T26D1519 | D8: 9500 | E8: =_xlfn.XLOOKUP(B8,COHVPI!A:A,COHVPI!E:E,0,0,1) -> 0 | F8: =_xlfn.XLOOKUP(B8,COHVPI!A:A,COHVPI!F:F) -> #N/A | G8: 466343 | H8: SA MONANGE CACHOS SH T | I8: 46151 | J8: 46151 | N8: =_xlfn.XLOOKUP('Linhas Rápidas'!B8,COHVPI!A:A,COHVPI!I:I) -> #N/A | O8: - | P8: OK | R8: 24042-2 | S8: MONANGE SH CACHOS DEFINIDOS 12X325ML | T8: 1961386 | U8: =_xlfn.XLOOKUP(T8,COHVPI!A:A,COHVPI!F:F) -> 0 | V8: =_xlfn.XLOOKUP(T8,COHVPI!A:A,COHVPI!I:I) -> 46151 | W8: =X8/12 -> 9600 | X8: =28800*4 -> 115200 | AD8: =VLOOKUP(B8,COHVPI!A:N,14,0) -> #N/A | AE8: =VLOOKUP(B8,COHVPI!A:E,5,0) -> #N/A | AF8: =AE8-D8 -> #N/A
A9: 10 | B9: 1961359 | C9: T26D1520 | D9: 9500 | E9: =_xlfn.XLOOKUP(B9,COHVPI!A:A,COHVPI!E:E,0,0,1) -> 0 | F9: =_xlfn.XLOOKUP(B9,COHVPI!A:A,COHVPI!F:F) -> #N/A | G9: 466343 | H9: SA MONANGE CACHOS SH T | I9: 46151 | J9: 46151 | N9: =_xlfn.XLOOKUP('Linhas Rápidas'!B9,COHVPI!A:A,COHVPI!I:I) -> #N/A | O9: - | P9: OK | AD9: =VLOOKUP(B9,COHVPI!A:N,14,0) -> #N/A | AE9: =VLOOKUP(B9,COHVPI!A:E,5,0) -> #N/A | AF9: =AE9-D9 -> #N/A
A10: 10 | B10: 1961360 | C10: T26D1521 | D10: 9500 | E10: =_xlfn.XLOOKUP(B10,COHVPI!A:A,COHVPI!E:E,0,0,1) -> 0 | F10: =_xlfn.XLOOKUP(B10,COHVPI!A:A,COHVPI!F:F) -> #N/A | G10: 466343 | H10: SA MONANGE CACHOS SH T | I10: 46151 | J10: 46151 | N10: =_xlfn.XLOOKUP('Linhas Rápidas'!B10,COHVPI!A:A,COHVPI!I:I) -> #N/A | O10: - | P10: OK | U10: =_xlfn.XLOOKUP(T10,COHVPI!A:A,COHVPI!F:F) -> #N/A | AD10: =VLOOKUP(B10,COHVPI!A:N,14,0) -> #N/A | AE10: =VLOOKUP(B10,COHVPI!A:E,5,0) -> #N/A | AF10: =AE10-D10 -> #N/A
A11: 10 | B11: 1961361 | C11: T26D1522 | D11: 9500 | E11: =_xlfn.XLOOKUP(B11,COHVPI!A:A,COHVPI!E:E,0,0,1) -> 0 | F11: =_xlfn.XLOOKUP(B11,COHVPI!A:A,COHVPI!F:F) -> #N/A | G11: 466343 | H11: SA MONANGE CACHOS SH T | I11: 46153 | J11: 46151 | N11: =_xlfn.XLOOKUP('Linhas Rápidas'!B11,COHVPI!A:A,COHVPI!I:I) -> #N/A | O11: - | P11: OK | AD11: =VLOOKUP(B11,COHVPI!A:N,14,0) -> #N/A | AE11: =VLOOKUP(B11,COHVPI!A:E,5,0) -> #N/A | AF11: =AE11-D11 -> #N/A
A12: 10 | B12: 1961362 | C12: T26D1523 | D12: 9500 | E12: =_xlfn.XLOOKUP(B12,COHVPI!A:A,COHVPI!E:E,0,0,1) -> 0 | F12: =_xlfn.XLOOKUP(B12,COHVPI!A:A,COHVPI!F:F) -> #N/A | G12: 466343 | H12: SA MONANGE CACHOS SH T | I12: 46153 | J12: 46151 | N12: =_xlfn.XLOOKUP('Linhas Rápidas'!B12,COHVPI!A:A,COHVPI!I:I) -> #N/A | O12: - | P12: OK | R12: 24042-2 | S12: MONANGE SH CACHOS DEFINIDOS 12X325ML | T12: 1961387 | U12: =_xlfn.XLOOKUP(T12,COHVPI!A:A,COHVPI!F:F) -> 0 | V12: =_xlfn.XLOOKUP(T12,COHVPI!A:A,COHVPI!I:I) -> 46153 | W12: =X12/12 -> 9600 | X12: 115200 | AD12: =VLOOKUP(B12,COHVPI!A:N,14,0) -> #N/A | AE12: =VLOOKUP(B12,COHVPI!A:E,5,0) -> #N/A | AF12: =AE12-D12 -> #N/A
A13: 10 | B13: 1961363 | C13: T26D1524 | D13: 9500 | E13: =_xlfn.XLOOKUP(B13,COHVPI!A:A,COHVPI!E:E,0,0,1) -> 0 | F13: =_xlfn.XLOOKUP(B13,COHVPI!A:A,COHVPI!F:F) -> #N/A | G13: 466343 | H13: SA MONANGE CACHOS SH T | I13: 46153 | J13: 46153 | N13: =_xlfn.XLOOKUP('Linhas Rápidas'!B13,COHVPI!A:A,COHVPI!I:I) -> #N/A | O13: - | P13: OK | AD13: =VLOOKUP(B13,COHVPI!A:N,14,0) -> #N/A | AE13: =VLOOKUP(B13,COHVPI!A:E,5,0) -> #N/A | AF13: =AE13-D13 -> #N/A
A14: 10 | B14: 1961364 | C14: T26D1525 | D14: 9500 | E14: =_xlfn.XLOOKUP(B14,COHVPI!A:A,COHVPI!E:E,0,0,1) -> 0 | F14: =_xlfn.XLOOKUP(B14,COHVPI!A:A,COHVPI!F:F) -> #N/A | G14: 466343 | H14: SA MONANGE CACHOS SH T | I14: 46154 | J14: 46153 | N14: =_xlfn.XLOOKUP('Linhas Rápidas'!B14,COHVPI!A:A,COHVPI!I:I) -> #N/A | O14: - | P14: OK | U14: =_xlfn.XLOOKUP(T14,COHVPI!A:A,COHVPI!F:F) -> #N/A | AD14: =VLOOKUP(B14,COHVPI!A:N,14,0) -> #N/A | AE14: =VLOOKUP(B14,COHVPI!A:E,5,0) -> #N/A | AF14: =AE14-D14 -> #N/A
A15: 10 | B15: 1961365 | C15: T26D1526 | D15: 9500 | E15: =_xlfn.XLOOKUP(B15,COHVPI!A:A,COHVPI!E:E,0,0,1) -> 0 | F15: =_xlfn.XLOOKUP(B15,COHVPI!A:A,COHVPI!F:F) -> #N/A | G15: 466343 | H15: SA MONANGE CACHOS SH T | I15: 46154 | J15: 46153 | N15: =_xlfn.XLOOKUP('Linhas Rápidas'!B15,COHVPI!A:A,COHVPI!I:I) -> #N/A | O15: - | P15: OK | AD15: =VLOOKUP(B15,COHVPI!A:N,14,0) -> #N/A | AE15: =VLOOKUP(B15,COHVPI!A:E,5,0) -> #N/A | AF15: =AE15-D15 -> #N/A
H16: LIMPEZA PARA COND MONANGE 325ML - 1 TURNO | R16: LIMPEZA PARA COND MONANGE 325ML - 1 TURNO | AD16: =VLOOKUP(B16,COHVPI!A:N,14,0) -> #N/A | AE16: =VLOOKUP(B16,COHVPI!A:E,5,0) -> #N/A | AF16: =AE16-D16 -> #N/A
A17: 10 | B17: 1961622 | C17: T26D1679 | D17: 9500 | E17: =_xlfn.XLOOKUP(A17,COHVPI!#REF!,COHVPI!E:E) -> #REF! | F17: =_xlfn.XLOOKUP(B17,COHVPI!A:A,COHVPI!F:F) -> #N/A | G17: 470365 | H17: SA MONANGE COND ACD HIALU | I17: 46153 | J17: 46153 | N17: =_xlfn.XLOOKUP('Linhas Rápidas'!B17,COHVPI!A:A,COHVPI!I:I) -> #N/A | O17: - | P17: OK | R17: 24051-3 | S17: MONANGE COND ACD HIALU 12X325ML | T17: 1961393 | U17: =_xlfn.XLOOKUP(T17,COHVPI!A:A,COHVPI!F:F) -> 0 | V17: =_xlfn.XLOOKUP(T17,COHVPI!A:A,COHVPI!I:I) -> 46158 | W17: =X17/12 -> 9940 | X17: =29820*4 -> 119280 | AD17: =VLOOKUP(B17,COHVPI!A:N,14,0) -> #N/A | AE17: =VLOOKUP(B17,COHVPI!A:E,5,0) -> #N/A | AF17: =AE17-D17 -> #N/A
A18: 10 | B18: 1961623 | C18: T26D1680 | D18: 9500 | E18: =_xlfn.XLOOKUP(A18,COHVPI!#REF!,COHVPI!E:E) -> #REF! | F18: =_xlfn.XLOOKUP(B18,COHVPI!A:A,COHVPI!F:F) -> #N/A | G18: 470365 | H18: SA MONANGE COND ACD HIALU | I18: 46153 | J18: 46153 | N18: =_xlfn.XLOOKUP('Linhas Rápidas'!B18,COHVPI!A:A,COHVPI!I:I) -> #N/A | O18: - | P18: OK | AD18: =VLOOKUP(B18,COHVPI!A:N,14,0) -> #N/A | AE18: =VLOOKUP(B18,COHVPI!A:E,5,0) -> #N/A | AF18: =AE18-D18 -> #N/A
A19: 10 | B19: 1961624 | C19: T26D1681 | D19: 9500 | E19: =_xlfn.XLOOKUP(A19,COHVPI!#REF!,COHVPI!E:E) -> #REF! | F19: =_xlfn.XLOOKUP(B19,COHVPI!A:A,COHVPI!F:F) -> #N/A | G19: 470365 | H19: SA MONANGE COND ACD HIALU | I19: 46153 | J19: 46153 | N19: =_xlfn.XLOOKUP('Linhas Rápidas'!B19,COHVPI!A:A,COHVPI!I:I) -> #N/A | O19: - | P19: OK | U19: =_xlfn.XLOOKUP(T19,COHVPI!A:A,COHVPI!F:F) -> 0 | AD19: =VLOOKUP(B19,COHVPI!A:N,14,0) -> #N/A | AE19: =VLOOKUP(B19,COHVPI!A:E,5,0) -> #N/A | AF19: =AE19-D19 -> #N/A
A20: 10 | B20: 1961625 | C20: T26D1682 | D20: 9500 | E20: =_xlfn.XLOOKUP(A20,COHVPI!#REF!,COHVPI!E:E) -> #REF! | F20: =_xlfn.XLOOKUP(B20,COHVPI!A:A,COHVPI!F:F) -> #N/A | G20: 470365 | H20: SA MONANGE COND ACD HIALU | I20: 46154 | J20: 46154 | N20: =_xlfn.XLOOKUP('Linhas Rápidas'!B20,COHVPI!A:A,COHVPI!I:I) -> #N/A | O20: - | P20: OK | AD20: =VLOOKUP(B20,COHVPI!A:N,14,0) -> #N/A | AE20: =VLOOKUP(B20,COHVPI!A:E,5,0) -> #N/A | AF20: =AE20-D20 -> #N/A
A21: 10 | B21: 1961286 | C21: T26D1447 | D21: 9500 | E21: =_xlfn.XLOOKUP(A21,COHVPI!#REF!,COHVPI!E:E) -> #REF! | F21: =_xlfn.XLOOKUP(B21,COHVPI!A:A,COHVPI!F:F) -> #N/A | G21: 466338 | H21: SA MONANGE QUIMICA CD T | I21: 46154 | J21: 46154 | N21: =_xlfn.XLOOKUP('Linhas Rápidas'!B21,COHVPI!A:A,COHVPI!I:I) -> #N/A | O21: PHASE OUT | P21: OK | R21: 24050-2 | S21: MONANGE COND REPARACAO POS Q 12X325ML | T21: 1961388 | U21: =_xlfn.XLOOKUP(T21,COHVPI!A:A,COHVPI!F:F) -> 0 | V21: =_xlfn.XLOOKUP(T21,COHVPI!A:A,COHVPI!I:I) -> 46154 | W21: =X21/12 -> 12425 | X21: =29820*5 -> 149100 | AD21: =VLOOKUP(B21,COHVPI!A:N,14,0) -> #N/A | AE21: =VLOOKUP(B21,COHVPI!A:E,5,0) -> #N/A | AF21: =AE21-D21 -> #N/A
A22: 10 | B22: 1961287 | C22: T26D1448 | D22: 9500 | E22: =_xlfn.XLOOKUP(A22,COHVPI!#REF!,COHVPI!E:E) -> #REF! | F22: =_xlfn.XLOOKUP(B22,COHVPI!A:A,COHVPI!F:F) -> #N/A | G22: 466338 | H22: SA MONANGE QUIMICA CD T | I22: 46154 | J22: 46154 | N22: =_xlfn.XLOOKUP('Linhas Rápidas'!B22,COHVPI!A:A,COHVPI!I:I) -> #N/A | O22: PHASE OUT | P22: TERMINA ATÉ DIA 09/05 | AD22: =VLOOKUP(B22,COHVPI!A:N,14,0) -> #N/A | AE22: =VLOOKUP(B22,COHVPI!A:E,5,0) -> #N/A | AF22: =AE22-D22 -> #N/A
A23: 10 | B23: 1961288 | C23: T26D1449 | D23: 9500 | G23: 466338 | H23: SA MONANGE QUIMICA CD T | I23: 46154 | J23: 46154 | O23: NA PORTA AG. RÓTULO 466466 | P23: TERMINA ATÉ DIA 09/05
A24: 10 | B24: 1961289 | C24: T26D1450 | D24: 9500 | E24: =_xlfn.XLOOKUP(A24,COHVPI!#REF!,COHVPI!E:E) -> #REF! | F24: =_xlfn.XLOOKUP(B24,COHVPI!A:A,COHVPI!F:F) -> #N/A | G24: 466338 | H24: SA MONANGE QUIMICA CD T | I24: 46155 | J24: 46154 | N24: =_xlfn.XLOOKUP('Linhas Rápidas'!B24,COHVPI!A:A,COHVPI!I:I) -> #N/A | O24: NA PORTA AG. RÓTULO 466466 | P24: TERMINA ATÉ DIA 09/05 | U24: =_xlfn.XLOOKUP(T24,COHVPI!A:A,COHVPI!F:F) -> #N/A | AD24: =VLOOKUP(B24,COHVPI!A:N,14,0) -> #N/A | AE24: =VLOOKUP(B24,COHVPI!A:E,5,0) -> #N/A | AF24: =AE24-D24 -> #N/A
A25: 10 | B25: 1961290 | C25: T26D1451 | D25: 9500 | E25: =_xlfn.XLOOKUP(A25,COHVPI!#REF!,COHVPI!E:E) -> #REF! | F25: =_xlfn.XLOOKUP(B25,COHVPI!A:A,COHVPI!F:F) -> #N/A | G25: 466338 | H25: SA MONANGE QUIMICA CD T | I25: 46155 | J25: 46154 | N25: =_xlfn.XLOOKUP('Linhas Rápidas'!B25,COHVPI!A:A,COHVPI!I:I) -> #N/A | O25: NA PORTA AG. RÓTULO 466466 | P25: TERMINA ATÉ DIA 09/05 | AD25: =VLOOKUP(B25,COHVPI!A:N,14,0) -> #N/A | AE25: =VLOOKUP(B25,COHVPI!A:E,5,0) -> #N/A | AF25: =AE25-D25 -> #N/A
A26: 10 | B26: 1961338 | C26: T26D1499 | D26: 9500 | E26: =_xlfn.XLOOKUP(A26,COHVPI!#REF!,COHVPI!E:E) -> #REF! | F26: =_xlfn.XLOOKUP(B26,COHVPI!A:A,COHVPI!F:F) -> #N/A | G26: 466334 | H26: SA MONANGE LISOS CD T | I26: 46155 | J26: 46155 | N26: =_xlfn.XLOOKUP('Linhas Rápidas'!B26,COHVPI!A:A,COHVPI!I:I) -> #N/A | O26: - | P26: OK | R26: 24048-2 | S26: MONANGE COND LISOS BRILHANTES 12X325ML | T26: 1961389 | U26: =_xlfn.XLOOKUP(T26,COHVPI!A:A,COHVPI!F:F) -> 0 | V26: =_xlfn.XLOOKUP(T26,COHVPI!A:A,COHVPI!I:I) -> 46155 | W26: =X26/12 -> 9940 | X26: =29820*4 -> 119280 | AD26: =VLOOKUP(B26,COHVPI!A:N,14,0) -> #N/A | AE26: =VLOOKUP(B26,COHVPI!A:E,5,0) -> #N/A | AF26: =AE26-D26 -> #N/A
A27: 10 | B27: 1961339 | C27: T26D1500 | D27: 9500 | E27: =_xlfn.XLOOKUP(A27,COHVPI!#REF!,COHVPI!E:E) -> #REF! | F27: =_xlfn.XLOOKUP(B27,COHVPI!A:A,COHVPI!F:F) -> #N/A | G27: 466334 | H27: SA MONANGE LISOS CD T | I27: 46155 | J27: 46155 | N27: =_xlfn.XLOOKUP('Linhas Rápidas'!B27,COHVPI!A:A,COHVPI!I:I) -> #N/A | O27: AG. RÓTULO 470896 | P27: OK | AD27: =VLOOKUP(B27,COHVPI!A:N,14,0) -> #N/A | AE27: =VLOOKUP(B27,COHVPI!A:E,5,0) -> #N/A | AF27: =AE27-D27 -> #N/A
A28: 10 | B28: 1961340 | C28: T26D1501 | D28: 9500 | E28: =_xlfn.XLOOKUP(A28,COHVPI!#REF!,COHVPI!E:E) -> #REF! | F28: =_xlfn.XLOOKUP(B28,COHVPI!A:A,COHVPI!F:F) -> #N/A | G28: 466334 | H28: SA MONANGE LISOS CD T | I28: 46155 | J28: 46155 | N28: =_xlfn.XLOOKUP('Linhas Rápidas'!B28,COHVPI!A:A,COHVPI!I:I) -> #N/A | O28: AG. RÓTULO 470896 | P28: OK | U28: =_xlfn.XLOOKUP(T28,COHVPI!A:A,COHVPI!F:F) -> #N/A | AD28: =VLOOKUP(B28,COHVPI!A:N,14,0) -> #N/A | AE28: =VLOOKUP(B28,COHVPI!A:E,5,0) -> #N/A | AF28: =AE28-D28 -> #N/A
A29: 10 | B29: 1961341 | C29: T26D1502 | D29: 9500 | E29: =_xlfn.XLOOKUP(A29,COHVPI!#REF!,COHVPI!E:E) -> #REF! | F29: =_xlfn.XLOOKUP(B29,COHVPI!A:A,COHVPI!F:F) -> #N/A | G29: 466334 | H29: SA MONANGE LISOS CD T | I29: 46156 | J29: 46155 | N29: =_xlfn.XLOOKUP('Linhas Rápidas'!B29,COHVPI!A:A,COHVPI!I:I) -> #N/A | O29: AG. RÓTULO 470896 | P29: OK | AD29: =VLOOKUP(B29,COHVPI!A:N,14,0) -> #N/A | AE29: =VLOOKUP(B29,COHVPI!A:E,5,0) -> #N/A | AF29: =AE29-D29 -> #N/A
A30: 10 | B30: 1961342 | C30: T26D1503 | D30: 9500 | E30: =_xlfn.XLOOKUP(A30,COHVPI!#REF!,COHVPI!E:E) -> #REF! | F30: =_xlfn.XLOOKUP(B30,COHVPI!A:A,COHVPI!F:F) -> #N/A | G30: 466334 | H30: SA MONANGE LISOS CD T | I30: 46156 | J30: 46155 | N30: =_xlfn.XLOOKUP('Linhas Rápidas'!B30,COHVPI!A:A,COHVPI!I:I) -> #N/A | O30: AG. RÓTULO 470896 | P30: OK | R30: 24048-2 | S30: MONANGE COND LISOS BRILHANTES 12X325ML | T30: 1961390 | U30: =_xlfn.XLOOKUP(T30,COHVPI!A:A,COHVPI!F:F) -> 0 | V30: =_xlfn.XLOOKUP(T30,COHVPI!A:A,COHVPI!I:I) -> 46156 | W30: =X30/12 -> 9940 | X30: =29820*4 -> 119280 | AD30: =VLOOKUP(B30,COHVPI!A:N,14,0) -> #N/A | AE30: =VLOOKUP(B30,COHVPI!A:E,5,0) -> #N/A | AF30: =AE30-D30 -> #N/A
A31: 10 | D31: 9500 | E31: =_xlfn.XLOOKUP(A31,COHVPI!#REF!,COHVPI!E:E) -> #REF! | F31: =_xlfn.XLOOKUP(B31,COHVPI!A:A,COHVPI!F:F) -> #N/A | G31: 466334 | H31: SA MONANGE LISOS CD T | I31: 46156 | J31: 46156 | N31: =_xlfn.XLOOKUP('Linhas Rápidas'!B31,COHVPI!A:A,COHVPI!I:I) -> #N/A | O31: AG. RÓTULO 470896 E RÓTULO 466464 | P31: OK | Z31: 1961343 | AA31: T26D1504 | AD31: =VLOOKUP(B31,COHVPI!A:N,14,0) -> #N/A | AE31: =VLOOKUP(B31,COHVPI!A:E,5,0) -> #N/A | AF31: =AE31-D31 -> #N/A
A32: 10 | D32: 9500 | E32: =_xlfn.XLOOKUP(A32,COHVPI!#REF!,COHVPI!E:E) -> #REF! | F32: =_xlfn.XLOOKUP(B32,COHVPI!A:A,COHVPI!F:F) -> #N/A | G32: 466334 | H32: SA MONANGE LISOS CD T | I32: 46156 | J32: 46156 | N32: =_xlfn.XLOOKUP('Linhas Rápidas'!B32,COHVPI!A:A,COHVPI!I:I) -> #N/A | O32: AG. RÓTULO 470896 E RÓTULO 466464 | P32: OK | U32: =_xlfn.XLOOKUP(T32,COHVPI!A:A,COHVPI!F:F) -> #N/A | Z32: 1961344 | AA32: T26D1505 | AD32: =VLOOKUP(B32,COHVPI!A:N,14,0) -> #N/A | AE32: =VLOOKUP(B32,COHVPI!A:E,5,0) -> #N/A | AF32: =AE32-D32 -> #N/A
A33: 10 | D33: 9500 | E33: =_xlfn.XLOOKUP(A33,COHVPI!#REF!,COHVPI!E:E) -> #REF! | F33: =_xlfn.XLOOKUP(B33,COHVPI!A:A,COHVPI!F:F) -> #N/A | G33: 466334 | H33: SA MONANGE LISOS CD T | I33: 46156 | J33: 46156 | N33: =_xlfn.XLOOKUP('Linhas Rápidas'!B33,COHVPI!A:A,COHVPI!I:I) -> #N/A | O33: AG. RÓTULO 470896 E RÓTULO 466464 | P33: OK | Z33: 1961345 | AA33: T26D1506 | AD33: =VLOOKUP(B33,COHVPI!A:N,14,0) -> #N/A | AE33: =VLOOKUP(B33,COHVPI!A:E,5,0) -> #N/A | AF33: =AE33-D33 -> #N/A
A34: 10 | B34: 1961330 | C34: T26D1491 | D34: 9500 | E34: =_xlfn.XLOOKUP(A34,COHVPI!#REF!,COHVPI!E:E) -> #REF! | F34: =_xlfn.XLOOKUP(B34,COHVPI!A:A,COHVPI!F:F) -> #N/A | G34: 466332 | H34: SA MONANGE HIDRATA CD T | I34: 46156 | J34: 46156 | N34: =_xlfn.XLOOKUP('Linhas Rápidas'!B34,COHVPI!A:A,COHVPI!I:I) -> #N/A | O34: - | P34: TERMINA DIA 09/05 | R34: 24047-2 | S34: MONANGE COND HIDRATACAO INT 12X325ML | T34: 1961391 | U34: =_xlfn.XLOOKUP(T34,COHVPI!A:A,COHVPI!F:F) -> 0 | V34: =_xlfn.XLOOKUP(T34,COHVPI!A:A,COHVPI!I:I) -> 46157 | W34: =X34/12 -> 9940 | X34: =29820*4 -> 119280 | AD34: =VLOOKUP(B34,COHVPI!A:N,14,0) -> #N/A | AE34: =VLOOKUP(B34,COHVPI!A:E,5,0) -> #N/A | AF34: =AE34-D34 -> #N/A
A35: 10 | B35: 1961331 | C35: T26D1492 | D35: 9500 | E35: =_xlfn.XLOOKUP(A35,COHVPI!#REF!,COHVPI!E:E) -> #REF! | F35: =_xlfn.XLOOKUP(B35,COHVPI!A:A,COHVPI!F:F) -> #N/A | G35: 466332 | H35: SA MONANGE HIDRATA CD T | I35: 46156 | J35: 46156 | N35: =_xlfn.XLOOKUP('Linhas Rápidas'!B35,COHVPI!A:A,COHVPI!I:I) -> #N/A | O35: - | P35: TERMINA DIA 09/05 | AD35: =VLOOKUP(B35,COHVPI!A:N,14,0) -> #N/A | AE35: =VLOOKUP(B35,COHVPI!A:E,5,0) -> #N/A | AF35: =AE35-D35 -> #N/A
A36: 10 | B36: 1961332 | C36: T26D1493 | D36: 9500 | E36: =_xlfn.XLOOKUP(A36,COHVPI!#REF!,COHVPI!E:E) -> #REF! | F36: =_xlfn.XLOOKUP(B36,COHVPI!A:A,COHVPI!F:F) -> #N/A | G36: 466332 | H36: SA MONANGE HIDRATA CD T | I36: 46156 | J36: 46156 | N36: =_xlfn.XLOOKUP('Linhas Rápidas'!B36,COHVPI!A:A,COHVPI!I:I) -> #N/A | O36: - | P36: TERMINA DIA 09/05 | U36: =_xlfn.XLOOKUP(T36,COHVPI!A:A,COHVPI!F:F) -> #N/A | AD36: =VLOOKUP(B36,COHVPI!A:N,14,0) -> #N/A | AE36: =VLOOKUP(B36,COHVPI!A:E,5,0) -> #N/A | AF36: =AE36-D36 -> #N/A
A37: 10 | B37: 1961333 | C37: T26D1494 | D37: 9500 | E37: =_xlfn.XLOOKUP(A37,COHVPI!#REF!,COHVPI!E:E) -> #REF! | F37: =_xlfn.XLOOKUP(B37,COHVPI!A:A,COHVPI!F:F) -> #N/A | G37: 466332 | H37: SA MONANGE HIDRATA CD T | I37: 46157 | J37: 46157 | N37: =_xlfn.XLOOKUP('Linhas Rápidas'!B37,COHVPI!A:A,COHVPI!I:I) -> #N/A | O37: - | P37: TERMINA DIA 09/05 | AD37: =VLOOKUP(B37,COHVPI!A:N,14,0) -> #N/A | AE37: =VLOOKUP(B37,COHVPI!A:E,5,0) -> #N/A | AF37: =AE37-D37 -> #N/A
A38: 10 | B38: 1961334 | C38: T26D1495 | D38: 9500 | E38: =_xlfn.XLOOKUP(A38,COHVPI!#REF!,COHVPI!E:E) -> #REF! | F38: =_xlfn.XLOOKUP(B38,COHVPI!A:A,COHVPI!F:F) -> #N/A | G38: 466332 | H38: SA MONANGE HIDRATA CD T | I38: 46157 | J38: 46157 | N38: =_xlfn.XLOOKUP('Linhas Rápidas'!B38,COHVPI!A:A,COHVPI!I:I) -> #N/A | O38: - | P38: TERMINA DIA 12/05 | R38: 24047-2 | S38: MONANGE COND HIDRATACAO INT 12X325ML | T38: 1961392 | U38: =_xlfn.XLOOKUP(T38,COHVPI!A:A,COHVPI!F:F) -> 0 | V38: =_xlfn.XLOOKUP(T38,COHVPI!A:A,COHVPI!I:I) -> 46157 | W38: =X38/12 -> 9940 | X38: =29820*4 -> 119280 | AD38: =VLOOKUP(B38,COHVPI!A:N,14,0) -> #N/A | AE38: =VLOOKUP(B38,COHVPI!A:E,5,0) -> #N/A | AF38: =AE38-D38 -> #N/A
A39: 10 | D39: 9500 | E39: =_xlfn.XLOOKUP(A39,COHVPI!#REF!,COHVPI!E:E) -> #REF! | F39: =_xlfn.XLOOKUP(B39,COHVPI!A:A,COHVPI!F:F) -> #N/A | G39: 466332 | H39: SA MONANGE HIDRATA CD T | I39: 46157 | J39: 46157 | N39: =_xlfn.XLOOKUP('Linhas Rápidas'!B39,COHVPI!A:A,COHVPI!I:I) -> #N/A | O39: NA PORTA AG. RÓTULO 466477/466463 | P39: TERMINA DIA 12/05 | Z39: 1961335 | AA39: T26D1496 | AD39: =VLOOKUP(B39,COHVPI!A:N,14,0) -> #N/A | AE39: =VLOOKUP(B39,COHVPI!A:E,5,0) -> #N/A | AF39: =AE39-D39 -> #N/A
A40: 10 | D40: 9500 | E40: =_xlfn.XLOOKUP(A40,COHVPI!#REF!,COHVPI!E:E) -> #REF! | F40: =_xlfn.XLOOKUP(B40,COHVPI!A:A,COHVPI!F:F) -> #N/A | G40: 466332 | H40: SA MONANGE HIDRATA CD T | I40: 46157 | J40: 46157 | N40: =_xlfn.XLOOKUP('Linhas Rápidas'!B40,COHVPI!A:A,COHVPI!I:I) -> #N/A | O40: NA PORTA AG. RÓTULO 466477/466463 | P40: TERMINA DIA 12/05 | U40: =_xlfn.XLOOKUP(T40,COHVPI!A:A,COHVPI!F:F) -> #N/A | Z40: 1961336 | AA40: T26D1497 | AD40: =VLOOKUP(B40,COHVPI!A:N,14,0) -> #N/A | AE40: =VLOOKUP(B40,COHVPI!A:E,5,0) -> #N/A | AF40: =AE40-D40 -> #N/A
A41: 10 | D41: 9500 | E41: =_xlfn.XLOOKUP(A41,COHVPI!#REF!,COHVPI!E:E) -> #REF! | F41: =_xlfn.XLOOKUP(B41,COHVPI!A:A,COHVPI!F:F) -> #N/A | G41: 466332 | H41: SA MONANGE HIDRATA CD T | I41: 46157 | J41: 46157 | N41: =_xlfn.XLOOKUP('Linhas Rápidas'!B41,COHVPI!A:A,COHVPI!I:I) -> #N/A | O41: NA PORTA AG. RÓTULO 466477/466463 | P41: TERMINA DIA 12/05 | Z41: 1961337 | AA41: T26D1498 | AD41: =VLOOKUP(B41,COHVPI!A:N,14,0) -> #N/A | AE41: =VLOOKUP(B41,COHVPI!A:E,5,0) -> #N/A | AF41: =AE41-D41 -> #N/A
...

Sheet COHVPI
A1: Ordem | B1: Nº do material | C1: Texto breve de material | D1: Lote | E1: Quantidade da ordem (GMEIN) | F1: Qtd.fornecida (GMEIN) | G1: Unidade de medida (=GMEIN) | H1: Planejador MRP | I1: Data-base iníc. | J1: Data de conclusão base | K1: Hr.início programada | L1: Fim program. (hora) | M1: Versão de produção | N1: Status do sistema
A2: 1962258 | B2: 15475-3 | C2: PAIXAO DEO LOCAO INSP ROSAS BRA 24X200ML | D2: 6125C1 | E2: 7830 | F2: 7725 | G2: CX | H2: Z03 | I2: 46147 | J2: 46148 | K2: 0.68199074 | L2: 0.68806713 | N2: ENTE MATF IMPR CNPA CAPC CPRE DMNV FRNP*
A3: 1961040 | B3: 15475-3 | C3: PAIXAO DEO LOCAO INSP ROSAS BRA 24X200ML | E3: 7830 | F3: 0 | G3: CX | H3: Z03 | I3: 46148 | J3: 46149 | K3: 0.27777778 | L3: 0.3474537 | N3: ABER CNAT DMNV NOLQ ORSL
A4: 1961450 | B4: 15475-3 | C4: PAIXAO DEO LOCAO INSP ROSAS BRA 24X200ML | E4: 7830 | F4: 0 | G4: CX | H4: Z03 | I4: 46156 | J4: 46157 | K4: 0.27777778 | L4: 0.3474537 | N4: ABER CNAT DMNV NOLQ ORSL
A5: 1961453 | B5: 15475-3 | C5: PAIXAO DEO LOCAO INSP ROSAS BRA 24X200ML | E5: 7830 | F5: 0 | G5: CX | H5: Z03 | I5: 46157 | J5: 46158 | K5: 0.27777778 | L5: 0.3474537 | N5: ABER CNAT DMNV NOLQ ORSL
A6: 1961456 | B6: 15475-3 | C6: PAIXAO DEO LOCAO INSP ROSAS BRA 24X200ML | E6: 7830 | F6: 0 | G6: CX | H6: Z03 | I6: 46158 | J6: 46160 | K6: 0.27777778 | L6: 0.3474537 | N6: ABER CNAT DMNV NOLQ ORSL
A7: 1961458 | B7: 15475-3 | C7: PAIXAO DEO LOCAO INSP ROSAS BRA 24X200ML | E7: 7830 | F7: 0 | G7: CX | H7: Z03 | I7: 46160 | J7: 46161 | K7: 0.27777778 | L7: 0.3474537 | N7: ABER CNAT DMNV NOLQ ORSL
A8: 1961461 | B8: 15476-3 | C8: PAIXAO DEO LOCAO IRRES FLOR LIS 24X200ML | E8: 7830 | F8: 0 | G8: CX | H8: Z03 | I8: 46161 | J8: 46162 | K8: 0.27777778 | L8: 0.3474537 | N8: ABER CNAT DMNV NOLQ ORSL
A9: 1961464 | B9: 15476-3 | C9: PAIXAO DEO LOCAO IRRES FLOR LIS 24X200ML | E9: 7830 | F9: 0 | G9: CX | H9: Z03 | I9: 46162 | J9: 46163 | K9: 0.27777778 | L9: 0.3474537 | N9: ABER CNAT DMNV NOLQ ORSL
A10: 1961424 | B10: 15492-3 | C10: PAIXAO DEO OLEO INSP ROSAS BRAN 12X200ML | E10: 8232 | F10: 0 | G10: CX | H10: Z03 | I10: 46158 | J10: 46159 | K10: 0.27777778 | L10: 0.15726852 | N10: ABER CNAT DMNV NOLQ ORSL
A11: 1961427 | B11: 15493-3 | C11: PAIXAO DEO OLEO IRRES FLOR LIS 12X200ML | E11: 8232 | F11: 0 | G11: CX | H11: Z03 | I11: 46160 | J11: 46161 | K11: 0.27777778 | L11: 0.15726852 | N11: ABER CNAT DMNV NOLQ ORSL
A12: 1961415 | B12: 15496-3 | C12: PAIXAO DEO OLEO TENT AMEIXA RUB 12X200ML | E12: 8232 | F12: 0 | G12: CX | H12: Z03 | I12: 46155 | J12: 46156 | K12: 0.27777778 | L12: 0.15726852 | N12: ABER CNAT DMNV NOLQ ORSL
A13: 1961418 | B13: 15496-3 | C13: PAIXAO DEO OLEO TENT AMEIXA RUB 12X200ML | E13: 8232 | F13: 0 | G13: CX | H13: Z03 | I13: 46156 | J13: 46157 | K13: 0.27777778 | L13: 0.15726852 | N13: ABER CNAT DMNV NOLQ ORSL
A14: 1961421 | B14: 15496-3 | C14: PAIXAO DEO OLEO TENT AMEIXA RUB 12X200ML | E14: 8232 | F14: 0 | G14: CX | H14: Z03 | I14: 46157 | J14: 46158 | K14: 0.27777778 | L14: 0.15726852 | N14: ABER CNAT DMNV NOLQ ORSL
... A25: 1961447 | B25: 18000-4 | C25: PAIXAO DEO LOCAO IRRES FLOR LIS 12X400ML | E25: 7806 | F25: 0 | G25: CX | H25: Z03 | I25: 46170 | J25: 46171 | K25: 0.27777778 | L25: 0.27854167 | N25: ABER CNAT DMNV NOLQ ORSL
A26: 1962547 | B26: 19340-4 | C26: PAIXAO DEO LOCAO TENT AMEIXA RU 12X400ML | D26: 6127C1 | E26: 7806 | F26: 0 | G26: CX | H26: Z03 | I26: 46149 | J26: 46150 | K26: 0.27777778 | L26: 0.27854167 | N26: LIB MATF IMPR CAPC CPRE LOAT NOLQ ORSL
A27: 1961428 | B27: 19340-4 | C27: PAIXAO DEO LOCAO TENT AMEIXA RU 12X400ML | E27: 7806 | F27: 0 | G27: CX | H27: Z03 | I27: 46150 | J27: 46151 | K27: 0.27777778 | L27: 0.27854167 | N27: ABER CNAT DMNV NOLQ ORSL
A28: 1961430 | B28: 19340-4 | C28: PAIXAO DEO LOCAO TENT AMEIXA RU 12X400ML | E28: 7806 | F28: 0 | G28: CX | H28: Z03 | I28: 46151 | J28: 46153 | K28: 0.27777778 | L28: 0.27854167 | N28: ABER CNAT DMNV NOLQ ORSL
A29: 1961423 | B29: 19340-4 | C29: PAIXAO DEO LOCAO TENT AMEIXA RU 12X400ML | E29: 5854 | F29: 0 | G29: CX | H29: Z03 | I29: 46153 | J29: 46154 | K29: 0.27777778 | L29: 0.028287037 | N29: ABER CNAT DMNV NOLQ ORSL
A30: 1961457 | B30: 20462-1 | C30: PAIXAO DEO OLEO AVELA 24X100ML | E30: 4116 | F30: 0 | G30: CX | H30: Z03 | I30: 46170 | J30: 46171 | K30: 0.27777778 | L30: 0.24126157 | N30: ABER CNAT DMNV NOLQ ORSL
A31: 1961459 | B31: 20462-1 | C31: PAIXAO DEO OLEO AVELA 24X100ML | E31: 4116 | F31: 0 | G31: CX | H31: Z03 | I31: 46171 | J31: 46172 | K31: 0.27777778 | L31: 0.24126157 | N31: ABER CNAT DMNV NOLQ ORSL
A32: 1961433 | B32: 20464-1 | C32: PAIXAO DEO OLEO TENT AMEIXA RU 24X100ML | E32: 4116 | F32: 0 | G32: CX | H32: Z03 | I32: 46162 | J32: 46163 | K32: 0.27777778 | L32: 0.24396991 | N32: ABER CNAT DMNV NOLQ ORSL
A33: 1959885 | B33: 20464-1 | C33: PAIXAO DEO OLEO TENT AMEIXA RU 24X100ML | E33: 4116 | F33: 0 | G33: CX | H33: Z03 | I33: 46172 | J33: 46173 | K33: 0.27777778 | L33: 0.24396991 | N33: ABER CNAT DMNV NOLQ ORSL
A34: 1959886 | B34: 20464-1 | C34: PAIXAO DEO OLEO TENT AMEIXA RU 24X100ML | E34: 4116 | F34: 0 | G34: CX | H34: Z03 | I34: 46174 | J34: 46175 | K34: 0.27777778 | L34: 0.24396991 | N34: ABER CNAT DMNV NOLQ ORSL
A35: 1962314 | B35: 24040-2 | C35: MONANGE SH HIDRATACAO INTENS 12X325ML | E35: 9600 | F35: 0 | G35: CX | H35: Z03 | I35: 46172 | J35: 46173 | K35: 0.27777778 | L35: 0.047013889 | N35: ABER CNAT DMNV NOLQ ORSL
A36: 1961407 | B36: 24041-2 | C36: MONANGE SH LISOS BRILHANTES 12X325ML | E36: 9600 | F36: 0 | G36: CX | H36: Z03 | I36: 46170 | J36: 46171 | K36: 0.27777778 | L36: 0.047013889 | N36: ABER CNAT DMNV NOLQ ORSL
A37: 1961409 | B37: 24041-2 | C37: MONANGE SH LISOS BRILHANTES 12X325ML | E37: 9600 | F37: 0 | G37: CX | H37: Z03 | I37: 46171 | J37: 46172 | K37: 0.27777778 | L37: 0.047013889 | N37: ABER CNAT DMNV NOLQ ORSL
A38: 1961386 | B38: 24042-2 | C38: MONANGE SH CACHOS DEFINIDOS 12X325ML | D38: 6128C1 | E38: 9600 | F38: 0 | G38: CX | H38: Z03 | I38: 46151 | J38: 46152 | K38: 0.27777778 | L38: 0.047013889 | N38: LIB MATF IMPR CAPC CPRE LOAT NOLQ ORSL
A39: 1961387 | B39: 24042-2 | C39: MONANGE SH CACHOS DEFINIDOS 12X325ML | E39: 9600 | F39: 0 | G39: CX | H39: Z03 | I39: 46153 | J39: 46154 | K39: 0.27777778 | L39: 0.047013889 | N39: ABER CNAT DMNV NOLQ ORSL
A40: 1962532 | B40: 24043-2 | C40: MONANGE SH REPARACAO POS QUI 12X325ML | D40: 6126C2 | E40: 9600 | F40: 9399 | G40: CX | H40: Z03 | I40: 46149 | J40: 46150 | K40: 0.27777778 | L40: 0.047013889 | N40: LIB MATF IMPR CNPA CAPC CPRE FRNP LOAT*
A41: 1962552 | B41: 24043-2 | C41: MONANGE SH REPARACAO POS QUI 12X325ML | D41: 6127C2 | E41: 9600 | F41: 8260 | G41: CX | H41: Z03 | I41: 46150 | J41: 46151 | K41: 0.27777778 | L41: 0.047013889 | N41: LIB MATF IMPR CNPA CAPC CPRE FRNP LOAT*
A42: 1961774 | B42: 24043-3 | C42: MONANGE SH REPARACAO BIOCOLAG 12X325ML | E42: 2400 | F42: 0 | G42: CX | H42: Z10 | I42: 46172 | J42: 46172 | K42: 0.27777778 | L42: 0.41327546 | N42: ABER CNAT DMNV NOLQ ORSL
A43: 1961406 | B43: 24044-3 | C43: MONANGE SH ACD HIALU 12X325ML | E43: 9600 | F43: 0 | G43: CX | H43: Z03 | I43: 46168 | J43: 46168 | K43: 0.27777778 | L43: 0.81325231 | N43: ABER CNAT DMNV NOLQ ORSL
A44: 1961408 | B44: 24044-3 | C44: MONANGE SH ACD HIALU 12X325ML | E44: 9600 | F44: 0 | G44: CX | H44: Z03 | I44: 46169 | J44: 46169 | K44: 0.27777778 | L44: 0.81325231 | N44: ABER CNAT DMNV NOLQ ORSL
A45: 1961382 | B45: 24045-2 | C45: MONANGE SH BOOST DE CRESC 12X325ML | D45: 6124C2 | E45: 9600 | F45: 9474 | G45: CX | H45: Z03 | I45: 46147 | J45: 46148 | K45: 0.65111111 | L45: 0.38621528 | N45: ENTE MATF IMPR CNPA CAPC CPRE DMNV FRNP*
A46: 1961384 | B46: 24045-2 | C46: MONANGE SH BOOST DE CRESC 12X325ML | D46: 6125C1 | E46: 9600 | F46: 0 | G46: CX | H46: Z03 | I46: 46148 | J46: 46149 | K46: 0.27777778 | L46: 0.047013889 | N46: LIB MATF IMPR CAPC CPRE LOAT MOME NOLQ*
A47: 1961399 | B47: 24046-2 | C47: MONANGE SH DETOXTERAPIA 12X325ML | E47: 9600 | F47: 0 | G47: CX | H47: Z03 | I47: 46164 | J47: 46165 | K47: 0.27777778 | L47: 0.047013889 | N47: ABER CNAT DMNV NOLQ ORSL
A48: 1961403 | B48: 24046-2 | C48: MONANGE SH DETOXTERAPIA 12X325ML | E48: 9600 | F48: 0 | G48: CX | H48: Z03 | I48: 46165 | J48: 46166 | K48: 0.27777778 | L48: 0.047013889 | N48: ABER CNAT DMNV NOLQ ORSL
A49: 1961404 | B49: 24046-2 | C49: MONANGE SH DETOXTERAPIA 12X325ML | E49: 9600 | F49: 0 | G49: CX | H49: Z03 | I49: 46167 | J49: 46168 | K49: 0.27777778 | L49: 0.047013889 | N49: ABER CNAT DMNV NOLQ ORSL
A50: 1961405 | B50: 24046-2 | C50: MONANGE SH DETOXTERAPIA 12X325ML | E50: 9600 | F50: 0 | G50: CX | H50: Z03 | I50: 46168 | J50: 46169 | K50: 0.27777778 | L50: 0.047013889 | N50: ABER CNAT DMNV NOLQ ORSL
...

Sheet RUN STRATEGY E PET X PAD
A1: Linha 10 - Condicionador | B1: 4 bulks
A2: Linha 10 - Shampoo | B2: 8 bulks
A3: Linha 12 | B3: 8 bulks
A4: Linha 13 | B4: 8 bulks
A5: SKUs com demanda menor, programar para 60 dias DOH
A6: Quando as linhas ficam somente 1 turno, a premissa é ficar pelo menos 2 dias com cada versão na linha
A10: PET (O MESMO FRASCO QUE VAI NO ÓLEO VAI NO HIDRATANTE NA L12):
A11: CACAU E PIMENTA
A12: BRIDGERTON
A13: FLOR DE BAUNILHA

Sheet Análise Gél
E6: 46139 | F6: =E6+1 -> 46140 | G6: =F6+1 -> 46141 | H6: =G6+1 -> 46142 | I6: =H6+1 -> 46143 | J6: =I6+1 -> 46144
E7: Seg | F7: Ter | G7: Qua | H7: Qui | I7: Sex | J7: Sáb | K7: Total Capacidade | L7: Total Ordens | M7: Sobra de Capacidade
F8: 0 | G8: 68000 | H8: =28000*2 -> 56000 | I8: 0 | J8: 0 | K8: =SUM(E8:J8) -> 124000 | L8: 133402 | M8: =K8-L8 -> -9402

Sheet MASTERDATA
A1: CODE | B1: DESCRIPTION | C1: UN | D1: PLANNER | E1: CATEGORY | F1: SALES SUB - CATEGORY | G1: SUB-CATEGORY | H1: LINE PRODUCTION | I1: LINHA RCCP | J1: SAFETY DAYS TOTAL | K1: CONV | L1: PLANO AGOSTO | M1: PRODUZIDO
A2: 10992-2 | B2: AVANCO DES SPRAY ACTION 12X85ML NVE | C2: CX | D2: Z03 | E2: DES SPRAY | F2: DESODORANTE | G2: AVANÇO | H2: L07 - ENV DESODORANTE SPRAY | I2: DESODORANTE_SPRAY | J2: 44 | K2: 12 | L2: 21132
A3: 771-5 | B3: AVANCO DES SPRAY ORIGINAL 12X85ML NVE | C3: CX | D3: Z03 | E3: DES SPRAY | F3: DESODORANTE | G3: AVANÇO | H3: L07 - ENV DESODORANTE SPRAY | I3: DESODORANTE_SPRAY | J3: 44 | K3: 12 | L3: 0
A4: 20279-0 | B4: BITUFO GD COCORICO C/F TUTI FRUTTI 90G | C4: CX | D4: Z08 | E4: CREME/GEL DENTAL | F4: ORAL CARE | G4: TRADICIONAL | H4: L35 - ENV CREME/GEL DENTAL BISN | I4: CD_GD_90G | J4: 15 | K4: 1 | L4: 0
A5: 20277-0 | B5: BITUFO GD COCORICO S/F MORANGO 90G | C5: CX | D5: Z08 | E5: CREME/GEL DENTAL | F5: ORAL CARE | G5: TRADICIONAL | H5: L35 - ENV CREME/GEL DENTAL BISN | I5: CD_GD_90G | J5: 22 | K5: 1 | L5: 0
A6: 20278-0 | B6: BITUFO GD COCORICO S/F TUTI FRUTTI 90G | C6: CX | D6: Z08 | E6: CREME/GEL DENTAL | F6: ORAL CARE | G6: TRADICIONAL | H6: L35 - ENV CREME/GEL DENTAL BISN | I6: CD_GD_90G | J6: 22 | K6: 1 | L6: 0
A7: 16768-5 | B7: BITUFO GD C FLUOR T FRUTI L TUNES 90G DL | C7: CX | D7: Z08 | E7: CREME/GEL DENTAL | F7: ORAL CARE | G7: TRADICIONAL | H7: L35 - ENV CREME/GEL DENTAL BISN | I7: CD_GD_90G | J7: 66 | K7: 1 | L7: 0
A8: 17297-2 | B8: BOZZANO BALSAMO POS HIDRAT 12X100G CIN | C8: CX | D8: Z08 | E8: BARBA BOZZANO | F8: PRÉ/PÓS BARBA | G8: BALSAMO POS BARBA BOZZANO | H8: L23 - ENV MANUAL ROT | I8: BARBA BOZZANO 100G | J8: 15 | K8: 12 | L8: 0
A9: 17298-2 | B9: BOZZANO BALSAMO POS PEL SENS 12X100G CIN | C9: CX | D9: Z08 | E9: BARBA BOZZANO | F9: PRÉ/PÓS BARBA | G9: BALSAMO POS BARBA BOZZANO | H9: L23 - ENV MANUAL ROT | I9: BARBA BOZZANO 100G | J9: 22 | K9: 12 | L9: 0
A10: 17299-2 | B10: BOZZANO GEL POS BARBA REFRES 12X100G CIN | C10: CX | D10: Z08 | E10: BARBA BOZZANO | F10: PRÉ/PÓS BARBA | G10: GEL POS BARBA BOZZANO | H10: L23 - ENV MANUAL ROT | I10: BARBA BOZZANO 100G | J10: 15 | K10: 12 | L10: 0
A11: 23473-1 | B11: BOZZANO GEL COND FAT2 BM 6X300G | C11: CX | D11: Z03 | E11: GEL MODELADOR BOZZANO | F11: MODELADOR DE CABELO | G11: BOZZANO 300G | H11: L08 - ENV GEL BOCA LARGA | I11: GEL_B.LARGA | J11: 44 | K11: 6 | L11: 0
A12: 23474-1 | B12: BOZZANO GEL COND FAT3 PROT SOLAR 6X300G | C12: CX | D12: Z03 | E12: GEL MODELADOR BOZZANO | F12: MODELADOR DE CABELO | G12: BOZZANO 300G | H12: L08 - ENV GEL BOCA LARGA | I12: GEL_B.LARGA | J12: 44 | K12: 6 | L12: 0
A13: 23475-1 | B13: BOZZANO GEL COND FAT4 6X300G | C13: CX | D13: Z03 | E13: GEL MODELADOR BOZZANO | F13: MODELADOR DE CABELO | G13: BOZZANO 300G | H13: L08 - ENV GEL BOCA LARGA | I13: GEL_B.LARGA | J13: 44 | K13: 6 | L13: 109440
... A170: 2475-6 | B170: LEITE COLONIA TOQUE C 24X200ML | C170: CX | D170: Z03 | E170: LEITE DE COLONIA | F170: CORPO | G170: LEITE DE COLONIA | H170: L06 - ENV LEITE COLONIA | I170: LEITE_COLONIA_200 | J170: 44 | K170: 24 | L170: 0
