Workbook
Name cad: [1]Cad_Sku!$1:$1048576
Name Plan5: #REF!
Name SegmentaçãodeDados_DATA_ENVASE: #N/A
Name semana: #REF!
Name semana: #REF!

Sheet Dinâmica
A3: DATA ENVASE | B3: LINHA | C3: CÓDIGO2 | D3: DESCRIÇÃO P.A | E3: Soma de QTD Programada (CX)
A4: 46156 | B4: L40 | C4: 17107-7 | D4: MONANGE DES ANTI SENSIVEL 12X90G NVF | E4: 14866
A5: 46156 | C5: 20257-4 | D5: MONANGE DES ANTIT INVISL 12X89G MT | E5: 22539
A6: 46156 | B6: L57 | C6: 27214-0 | D6: BOZZANO DES ANTI EXTREME SPORT 12X200ML | E6: 16725
A7: 46156 | B7: (vazio) | C7: (vazio) | D7: (vazio)
A8: 46157 | B8: L40 | C8: 20257-4 | D8: MONANGE DES ANTIT INVISL 12X89G MT | E8: 22539
A9: 46157 | C9: 25004-1 | D9: BOZZANO DES ANTI CARVAO 12X90G NVF | E9: 14866
A10: 46157 | C10: 25503-1 | D10: MONANGE DES ANTIT ESPORTE AERO 12X90G MT | E10: 21246
A11: 46157 | B11: L57 | C11: 29555-1 | D11: MONANGE DES ANTIT PROT SEC 12X200ML MT | E11: 11150
A12: 46157 | B12: (vazio) | C12: (vazio) | D12: (vazio)
A13: 46158 | B13: L40 | C13: 17111-7 | D13: MONANGE DES ANTIT HIDR INTEN 12X90G MT | E13: 22299
A14: 46158 | B14: L57 | C14: 27212-1 | D14: MONANGE DES ANTIT FR VM 12X200ML MT | E14: 11150
A15: 46158 | B15: (vazio) | C15: (vazio) | D15: (vazio)
A16: 46160 | B16: 0 | C16: 25503-1 | D16: MONANGE DES ANTIT ESPORTE AERO 12X90G MT | E16: 21246
A17: 46160 | B17: L40 | C17: 25004-1 | D17: BOZZANO DES ANTI CARVAO 12X90G NVF | E17: 14866
A18: 46160 | B18: L57 | C18: 29554-0 | D18: BOZZANO DES ANTIT ANTIBAC FRESH 12X200ML | E18: 11150
A19: 46160 | B19: (vazio) | C19: (vazio) | D19: (vazio)
A20: 46161 | B20: L40 | C20: 13441-6 | D20: BOZZANO DES ANTI S PERF SENS 12X90G NVF | E20: 21237
A21: 46161 | C21: 17111-7 | D21: MONANGE DES ANTIT HIDR INTEN 12X90G MT | E21: 22299
A22: 46161 | B22: L57 | C22: 29554-0 | D22: BOZZANO DES ANTIT ANTIBAC FRESH 12X200ML | E22: 11150
A23: 46161 | B23: (vazio) | C23: (vazio) | D23: (vazio)
A24: 46162 | B24: 0 | C24: 29554-0 | D24: BOZZANO DES ANTIT ANTIBAC FRESH 12X200ML | E24: 11150
A25: 46162 | B25: L40 | C25: 17110-8 | D25: MONANGE DES ANTIT FRTS VM 12X90G MT | E25: 22299
A26: 46162 | B26: (vazio) | C26: 20257-3 | D26: MONANGE DES ANTI INVISIVEL 12X89G NVF
A27: 46162 | C27: (vazio) | D27: (vazio)
A28: 46163 | B28: 0 | C28: 25003-1 | D28: BOZZANO DES ANTI DRY 12X90G NVF | E28: 7433
A29: 46163 | B29: L40 | C29: 17109-7 | D29: MONANGE DES ANTIT FL LAV 12X90G MT | E29: 22299
A30: 46163 | C30: 17110-8 | D30: MONANGE DES ANTIT FRTS VM 12X90G MT | E30: 22299
A31: 46163 | B31: L57 | C31: 27213-1 | D31: MONANGE DES ANTIT INVIS 12X200ML MT | E31: 11238
A32: 46163 | B32: (vazio) | C32: (vazio) | D32: (vazio)
A33: 46164 | B33: L40 | C33: 25645-0 | D33: BOZZANO CLINIC ULTRA COOL AERO 12X94G | E33: 8488
A34: 46164 | B34: (vazio) | C34: (vazio) | D34: (vazio)
A35: 46165 | B35: 0 | C35: 17111-7 | D35: MONANGE DES ANTIT HIDR INTEN 12X90G MT | E35: 14866
A36: 46165 | B36: L40 | C36: 17109-7 | D36: MONANGE DES ANTIT FL LAV 12X90G MT | E36: 22299
A37: 46165 | C37: 17110-8 | D37: MONANGE DES ANTIT FRTS VM 12X90G MT | E37: 22299
A38: 46165 | B38: (vazio) | C38: (vazio) | D38: (vazio)
A39: 46167 | B39: 0 | C39: 17109-7 | D39: MONANGE DES ANTIT FL LAV 12X90G MT | E39: 14866
A40: 46167 | C40: 17111-7 | D40: MONANGE DES ANTIT HIDR INTEN 12X90G MT | E40: 14866
A41: 46167 | B41: L40 | C41: 17110-8 | D41: MONANGE DES ANTIT FRTS VM 12X90G MT | E41: 22299
A42: 46167 | B42: L57 | C42: 29552-0 | D42: BOZZANO DES ANTIT CARVAO ATIV 12X200ML | E42: 16725
...

Sheet INDICADOR DE RENDIMENTO MENSAL
R1: RESUMO MENSAL POR SKU
A2: LINHA | B2: CÓDIGO | C2: DESCRIÇÃO P.A | D2: ORDEM | E2: Data Início | F2: Data Fim | G2: QTD OP | H2: QTD REALIZADA | I2: RENDIMENTO | L2: CÓDIGO | M2: DESCRIÇÃO P.A | N2: Soma de QTD OP | O2: Soma de QTD REALIZADA | P2: Rendimento Geral | R2: CÓDIGO | S2: DESCRIÇÃO P.A | T2: Soma de QTD OP | U2: Soma de QTD REALIZADA | V2: RENDIMENTO GERAL
A3: L40 | B3: 25643-2 | C3: MONANGE CLIN REVIG AERO 12X94G MT | D3: 1960517 | E3: =_xlfn.XLOOKUP(D3,'COHVPI DATAS REALIZADAS'!C:C,'COHVPI DATAS REALIZADAS'!N:N,0,0,1) -> 0 | F3: =_xlfn.XLOOKUP(D3,'COHVPI DATAS REALIZADAS'!C:C,'COHVPI DATAS REALIZADAS'!O:O,0,0,1) -> 0 | G3: =_xlfn.XLOOKUP(D3,COHVPI!A:A,COHVPI!E:E,0,0,1) -> 0 | H3: =_xlfn.XLOOKUP(D3,COHVPI!A:A,COHVPI!F:F,0,0,1) -> 0 | I3: =H3/G3 -> #DIV/0! | L3: 10909-3 | M3: BOZZANO ESPUMA BARBA REFRES 6X193G CIN | N3: 13330 | O3: 12971 | P3: =O3/N3 -> 0.97306827 | R3: 8627-4 | S3: TRES MARCHAND DES ANTI CLASS 12X90G NVF | T3: 6457 | U3: 7132 | V3: 1.1045377
A4: L40 | B4: 25644-0 | C4: BOZZANO CLINICAL CLEAN AERO 12X94G | D4: 1960536 | E4: =_xlfn.XLOOKUP(D4,'COHVPI DATAS REALIZADAS'!C:C,'COHVPI DATAS REALIZADAS'!N:N,0,0,1) -> 46143 | F4: =_xlfn.XLOOKUP(D4,'COHVPI DATAS REALIZADAS'!C:C,'COHVPI DATAS REALIZADAS'!O:O,0,0,1) -> 46144 | G4: =_xlfn.XLOOKUP(D4,COHVPI!A:A,COHVPI!E:E,0,0,1) -> 8488 | H4: =_xlfn.XLOOKUP(D4,COHVPI!A:A,COHVPI!F:F,0,0,1) -> 8160 | I4: =H4/G4 -> 0.96135721 | L4: 13441-6 | M4: BOZZANO DES ANTI S PERF SENS 12X90G NVF | N4: 42474 | O4: 43802 | P4: =O4/N4 -> 1.0312662 | R4: 25643-2 | S4: MONANGE CLIN REVIG AERO 12X94G MT | T4: 8488 | U4: 9248 | V4: 1.0895382
A5: L40 | B5: 8627-4 | C5: TRES MARCHAND DES ANTI CLASS 12X90G NVF | D5: 1959059 | E5: =_xlfn.XLOOKUP(D5,'COHVPI DATAS REALIZADAS'!C:C,'COHVPI DATAS REALIZADAS'!N:N,0,0,1) -> 46146 | F5: =_xlfn.XLOOKUP(D5,'COHVPI DATAS REALIZADAS'!C:C,'COHVPI DATAS REALIZADAS'!O:O,0,0,1) -> 46146 | G5: =_xlfn.XLOOKUP(D5,COHVPI!A:A,COHVPI!E:E,0,0,1) -> 6457 | H5: =_xlfn.XLOOKUP(D5,COHVPI!A:A,COHVPI!F:F,0,0,1) -> 7132 | I5: =H5/G5 -> 1.1045377 | L5: 17107-7 | M5: MONANGE DES ANTI SENSIVEL 12X90G NVF | N5: 14866 | O5: 14553 | P5: =O5/N5 -> 0.97894524 | R5: 13441-6 | S5: BOZZANO DES ANTI S PERF SENS 12X90G NVF | T5: 42474 | U5: 43802 | V5: 1.0312662
A6: L40 | B6: 24631-2 | C6: MONANGE DES ANTIT PROT SEC 12X90G MT | D6: 1960792 | E6: =_xlfn.XLOOKUP(D6,'COHVPI DATAS REALIZADAS'!C:C,'COHVPI DATAS REALIZADAS'!N:N,0,0,1) -> 46147 | F6: =_xlfn.XLOOKUP(D6,'COHVPI DATAS REALIZADAS'!C:C,'COHVPI DATAS REALIZADAS'!O:O,0,0,1) -> 46149 | G6: =_xlfn.XLOOKUP(D6,COHVPI!A:A,COHVPI!E:E,0,0,1) -> 22299 | H6: =_xlfn.XLOOKUP(D6,COHVPI!A:A,COHVPI!F:F,0,0,1) -> 21600 | I6: =H6/G6 -> 0.9686533 | L6: 17109-6 | M6: MONANGE DES ANTI FLOR LAV 12X90G NVF | N6: 14866 | O6: 14628 | P6: =O6/N6 -> 0.98399031 | R6: 27213-1 | S6: MONANGE DES ANTIT INVIS 12X200ML MT | T6: 11238 | U6: 11560 | V6: 1.0286528
A7: L40 | B7: 24631-2 | C7: MONANGE DES ANTIT PROT SEC 12X90G MT | D7: 1960789 | E7: =_xlfn.XLOOKUP(D7,'COHVPI DATAS REALIZADAS'!C:C,'COHVPI DATAS REALIZADAS'!N:N,0,0,1) -> 46148 | F7: =_xlfn.XLOOKUP(D7,'COHVPI DATAS REALIZADAS'!C:C,'COHVPI DATAS REALIZADAS'!O:O,0,0,1) -> 46150 | G7: =_xlfn.XLOOKUP(D7,COHVPI!A:A,COHVPI!E:E,0,0,1) -> 14866 | H7: =_xlfn.XLOOKUP(D7,COHVPI!A:A,COHVPI!F:F,0,0,1) -> 14160 | I7: =H7/G7 -> 0.95250908 | L7: 17109-7 | M7: MONANGE DES ANTIT FL LAV 12X90G MT | N7: 104062 | O7: 101766 | P7: =O7/N7 -> 0.97793623 | R7: 20257-4 | S7: MONANGE DES ANTIT INVISL 12X89G MT | T7: 90156 | U7: 92605 | V7: 1.027164
A8: L40 | B8: 24631-2 | C8: MONANGE DES ANTIT PROT SEC 12X90G MT | D8: 1960790 | E8: =_xlfn.XLOOKUP(D8,'COHVPI DATAS REALIZADAS'!C:C,'COHVPI DATAS REALIZADAS'!N:N,0,0,1) -> 46150 | F8: =_xlfn.XLOOKUP(D8,'COHVPI DATAS REALIZADAS'!C:C,'COHVPI DATAS REALIZADAS'!O:O,0,0,1) -> 46151 | G8: =_xlfn.XLOOKUP(D8,COHVPI!A:A,COHVPI!E:E,0,0,1) -> 14866 | H8: =_xlfn.XLOOKUP(D8,COHVPI!A:A,COHVPI!F:F,0,0,1) -> 14640 | I8: =H8/G8 -> 0.98479752 | L8: 17110-8 | M8: MONANGE DES ANTIT FRTS VM 12X90G MT | N8: 163526 | O8: 164733 | P8: =O8/N8 -> 1.0073811 | R8: 25503-1 | S8: MONANGE DES ANTIT ESPORTE AERO 12X90G MT | T8: 35410 | U8: 36177 | V8: 1.0216605
A9: L40 | B9: 24631-2 | C9: MONANGE DES ANTIT PROT SEC 12X90G MT | D9: 1960791 | E9: =_xlfn.XLOOKUP(D9,'COHVPI DATAS REALIZADAS'!C:C,'COHVPI DATAS REALIZADAS'!N:N,0,0,1) -> 46151 | F9: =_xlfn.XLOOKUP(D9,'COHVPI DATAS REALIZADAS'!C:C,'COHVPI DATAS REALIZADAS'!O:O,0,0,1) -> 46153 | G9: =_xlfn.XLOOKUP(D9,COHVPI!A:A,COHVPI!E:E,0,0,1) -> 14866 | H9: =_xlfn.XLOOKUP(D9,COHVPI!A:A,COHVPI!F:F,0,0,1) -> 14721 | I9: =H9/G9 -> 0.9902462 | L9: 17111-6 | M9: MONANGE DES ANTI HIDR INTEN 12X90G NVF | N9: 14866 | O9: 14517 | P9: =O9/N9 -> 0.97652361 | R9: 27211-0 | S9: MONANGE DES ANTI HIDR INTENSIVA 12X200ML | T9: 5309 | U9: 5370 | V9: 1.0114899
A10: L40 | B10: 17109-6 | C10: MONANGE DES ANTI FLOR LAV 12X90G NVF | D10: 1962558 | E10: =_xlfn.XLOOKUP(D10,'COHVPI DATAS REALIZADAS'!C:C,'COHVPI DATAS REALIZADAS'!N:N,0,0,1) -> 46153 | F10: =_xlfn.XLOOKUP(D10,'COHVPI DATAS REALIZADAS'!C:C,'COHVPI DATAS REALIZADAS'!O:O,0,0,1) -> 46155 | G10: =_xlfn.XLOOKUP(D10,COHVPI!A:A,COHVPI!E:E,0,0,1) -> 14866 | H10: =_xlfn.XLOOKUP(D10,COHVPI!A:A,COHVPI!F:F,0,0,1) -> 14628 | I10: =H10/G10 -> 0.98399031 | L10: 17111-7 | M10: MONANGE DES ANTIT HIDR INTEN 12X90G MT | N10: 163526 | O10: 164237 | P10: =O10/N10 -> 1.0043479 | R10: 17110-8 | S10: MONANGE DES ANTIT FRTS VM 12X90G MT | T10: 163526 | U10: 164733 | V10: 1.0073811
A11: L40 | B11: 17111-6 | C11: MONANGE DES ANTI HIDR INTEN 12X90G NVF | D11: 1962536 | E11: =_xlfn.XLOOKUP(D11,'COHVPI DATAS REALIZADAS'!C:C,'COHVPI DATAS REALIZADAS'!N:N,0,0,1) -> 46155 | F11: =_xlfn.XLOOKUP(D11,'COHVPI DATAS REALIZADAS'!C:C,'COHVPI DATAS REALIZADAS'!O:O,0,0,1) -> 46156 | G11: =_xlfn.XLOOKUP(D11,COHVPI!A:A,COHVPI!E:E,0,0,1) -> 14866 | H11: =_xlfn.XLOOKUP(D11,COHVPI!A:A,COHVPI!F:F,0,0,1) -> 14517 | I11: =H11/G11 -> 0.97652361 | L11: 17425-5 | M11: BOZZANO DES ANTI ANTBAC FRESH 12X90G NVF | N11: 52031 | O11: 51444 | P11: =O11/N11 -> 0.98871826 | R11: 17111-7 | S11: MONANGE DES ANTIT HIDR INTEN 12X90G MT | T11: 163526 | U11: 164237 | V11: 1.0043479
A12: L40 | B12: 17107-7 | C12: MONANGE DES ANTI SENSIVEL 12X90G NVF | D12: 1962321 | E12: =_xlfn.XLOOKUP(D12,'COHVPI DATAS REALIZADAS'!C:C,'COHVPI DATAS REALIZADAS'!N:N,0,0,1) -> 46156 | F12: =_xlfn.XLOOKUP(D12,'COHVPI DATAS REALIZADAS'!C:C,'COHVPI DATAS REALIZADAS'!O:O,0,0,1) -> 46157 | G12: =_xlfn.XLOOKUP(D12,COHVPI!A:A,COHVPI!E:E,0,0,1) -> 14866 | H12: =_xlfn.XLOOKUP(D12,COHVPI!A:A,COHVPI!F:F,0,0,1) -> 14553 | I12: =H12/G12 -> 0.97894524 | L12: 18998-5 | M12: BOZZANO DES ANTI EXTREM SPORT 12X90G NVF | N12: 44598 | O12: 43926 | P12: =O12/N12 -> 0.98493206 | R12: 23209-5 | S12: ADIDAS DES ANTI PRO INVISIBLE MASC 150ML | T12: 15026 | U12: 14980 | V12: 0.99693864
A13: L40 | B13: 20257-3 | C13: MONANGE DES ANTI INVISIVEL 12X89G NVF | D13: 1963047 | E13: =_xlfn.XLOOKUP(D13,'COHVPI DATAS REALIZADAS'!C:C,'COHVPI DATAS REALIZADAS'!N:N,0,0,1) -> 46157 | F13: =_xlfn.XLOOKUP(D13,'COHVPI DATAS REALIZADAS'!C:C,'COHVPI DATAS REALIZADAS'!O:O,0,0,1) -> 46158 | G13: =_xlfn.XLOOKUP(D13,COHVPI!A:A,COHVPI!E:E,0,0,1) -> 7513 | H13: =_xlfn.XLOOKUP(D13,COHVPI!A:A,COHVPI!F:F,0,0,1) -> 7473 | I13: =H13/G13 -> 0.9946759 | L13: 20257-3 | M13: MONANGE DES ANTI INVISIVEL 12X89G NVF | N13: 7513 | O13: 7473 | P13: =O13/N13 -> 0.9946759 | R13: 29554-0 | S13: BOZZANO DES ANTIT ANTIBAC FRESH 12X200ML | T13: 44600 | U13: 44460 | V13: 0.99686099
A14: L40 | B14: 25503-1 | C14: MONANGE DES ANTIT ESPORTE AERO 12X90G MT | D14: 1962322 | E14: =_xlfn.XLOOKUP(D14,'COHVPI DATAS REALIZADAS'!C:C,'COHVPI DATAS REALIZADAS'!N:N,0,0,1) -> 46158 | F14: =_xlfn.XLOOKUP(D14,'COHVPI DATAS REALIZADAS'!C:C,'COHVPI DATAS REALIZADAS'!O:O,0,0,1) -> 46161 | G14: =_xlfn.XLOOKUP(D14,COHVPI!A:A,COHVPI!E:E,0,0,1) -> 21246 | H14: =_xlfn.XLOOKUP(D14,COHVPI!A:A,COHVPI!F:F,0,0,1) -> 21575 | I14: =H14/G14 -> 1.0154853 | L14: 20257-4 | M14: MONANGE DES ANTIT INVISL 12X89G MT | N14: 90156 | O14: 92605 | P14: =O14/N14 -> 1.027164 | R14: 27212-0 | S14: MONANGE DES ANTI FR VERMELHAS 12X200ML | T14: 5574.5 | U14: 5555 | V14: 0.99650193
... A20: L40 | B20: 17109-7 | C20: MONANGE DES ANTIT FL LAV 12X90G MT | D20: 1962329 | E20: =_xlfn.XLOOKUP(D20,'COHVPI DATAS REALIZADAS'!C:C,'COHVPI DATAS REALIZADAS'!N:N,0,0,1) -> 46171 | F20: =_xlfn.XLOOKUP(D20,'COHVPI DATAS REALIZADAS'!C:C,'COHVPI DATAS REALIZADAS'!O:O,0,0,1) -> 46172 | G20: =_xlfn.XLOOKUP(D20,COHVPI!A:A,COHVPI!E:E,0,0,1) -> 14866 | H20: =_xlfn.XLOOKUP(D20,COHVPI!A:A,COHVPI!F:F,0,0,1) -> 14640 | I20: =H20/G20 -> 0.98479752 | L20: 25503-1 | M20: MONANGE DES ANTIT ESPORTE AERO 12X90G MT | N20: 35410 | O20: 36177 | P20: =O20/N20 -> 1.0216605 | R20: 27211-1 | S20: MONANGE DES ANTIT HIDR INTEN 12X200ML MT | T20: 50175 | U20: 49477 | V20: 0.98608869
A21: TOTAL L40 | G21: =SUM(G3:G20) -> 273425 | H21: =SUM(H3:H20) -> 269527 | I21: =H21/G21 -> 0.98574381 | L21: 25643-2 | M21: MONANGE CLIN REVIG AERO 12X94G MT | N21: 8488 | O21: 9248 | P21: =O21/N21 -> 1.0895382 | R21: 27214-0 | S21: BOZZANO DES ANTI EXTREME SPORT 12X200ML | T21: 33450 | U21: 32974 | V21: 0.98576981
A22: L53 | B22: 13441-6 | C22: BOZZANO DES ANTI S PERF SENS 12X90G NVF | D22: 1960532 | E22: =_xlfn.XLOOKUP(D22,'COHVPI DATAS REALIZADAS'!C:C,'COHVPI DATAS REALIZADAS'!N:N,0,0,1) -> 0 | F22: =_xlfn.XLOOKUP(D22,'COHVPI DATAS REALIZADAS'!C:C,'COHVPI DATAS REALIZADAS'!O:O,0,0,1) -> 0 | G22: =_xlfn.XLOOKUP(D22,COHVPI!A:A,COHVPI!E:E,0,0,1) -> 0 | H22: =_xlfn.XLOOKUP(D22,COHVPI!A:A,COHVPI!F:F,0,0,1) -> 0 | I22: =H22/G22 -> #DIV/0! | L22: 25644-0 | M22: BOZZANO CLINICAL CLEAN AERO 12X94G | N22: 8488 | O22: 8160 | P22: =O22/N22 -> 0.96135721 | R22: 18998-5 | S22: BOZZANO DES ANTI EXTREM SPORT 12X90G NVF | T22: 44598 | U22: 43926 | V22: 0.98493206
A23: L53 | B23: 13441-6 | C23: BOZZANO DES ANTI S PERF SENS 12X90G NVF | D23: 1960534 | E23: =_xlfn.XLOOKUP(D23,'COHVPI DATAS REALIZADAS'!C:C,'COHVPI DATAS REALIZADAS'!N:N,0,0,1) -> 46144 | F23: =_xlfn.XLOOKUP(D23,'COHVPI DATAS REALIZADAS'!C:C,'COHVPI DATAS REALIZADAS'!O:O,0,0,1) -> 46146 | G23: =_xlfn.XLOOKUP(D23,COHVPI!A:A,COHVPI!E:E,0,0,1) -> 7079 | H23: =_xlfn.XLOOKUP(D23,COHVPI!A:A,COHVPI!F:F,0,0,1) -> 7392 | I23: =H23/G23 -> 1.0442153 | L23: 25645-0 | M23: BOZZANO CLINIC ULTRA COOL AERO 12X94G | N23: 8488 | O23: 8457 | P23: =O23/N23 -> 0.99634779 | R23: 29553-0 | S23: BOZZANO DES ANTIT DRY 12X200ML | T23: 33450 | U23: 32935 | V23: 0.98460389
A24: L53 | B24: 18998-5 | C24: BOZZANO DES ANTI EXTREM SPORT 12X90G NVF | D24: 1960535 | E24: =_xlfn.XLOOKUP(D24,'COHVPI DATAS REALIZADAS'!C:C,'COHVPI DATAS REALIZADAS'!N:N,0,0,1) -> 46146 | F24: =_xlfn.XLOOKUP(D24,'COHVPI DATAS REALIZADAS'!C:C,'COHVPI DATAS REALIZADAS'!O:O,0,0,1) -> 46148 | G24: =_xlfn.XLOOKUP(D24,COHVPI!A:A,COHVPI!E:E,0,0,1) -> 14866 | H24: =_xlfn.XLOOKUP(D24,COHVPI!A:A,COHVPI!F:F,0,0,1) -> 14160 | I24: =H24/G24 -> 0.95250908 | L24: 27211-0 | M24: MONANGE DES ANTI HIDR INTENSIVA 12X200ML | N24: 5309 | O24: 5370 | P24: =O24/N24 -> 1.0114899 | R24: 17109-6 | S24: MONANGE DES ANTI FLOR LAV 12X90G NVF | T24: 14866 | U24: 14628 | V24: 0.98399031
A25: L53 | B25: 18998-5 | C25: BOZZANO DES ANTI EXTREM SPORT 12X90G NVF | D25: 1960537 | E25: =_xlfn.XLOOKUP(D25,'COHVPI DATAS REALIZADAS'!C:C,'COHVPI DATAS REALIZADAS'!N:N,0,0,1) -> 46148 | F25: =_xlfn.XLOOKUP(D25,'COHVPI DATAS REALIZADAS'!C:C,'COHVPI DATAS REALIZADAS'!O:O,0,0,1) -> 46149 | G25: =_xlfn.XLOOKUP(D25,COHVPI!A:A,COHVPI!E:E,0,0,1) -> 14866 | H25: =_xlfn.XLOOKUP(D25,COHVPI!A:A,COHVPI!F:F,0,0,1) -> 14640 | I25: =H25/G25 -> 0.98479752 | L25: 27211-1 | M25: MONANGE DES ANTIT HIDR INTEN 12X200ML MT | N25: 50175 | O25: 49477 | P25: =O25/N25 -> 0.98608869 | R25: 29555-1 | S25: MONANGE DES ANTIT PROT SEC 12X200ML MT | T25: 11150 | U25: 10931 | V25: 0.98035874
A26: L53 | B26: 18998-5 | C26: BOZZANO DES ANTI EXTREM SPORT 12X90G NVF | D26: 1960538 | E26: =_xlfn.XLOOKUP(D26,'COHVPI DATAS REALIZADAS'!C:C,'COHVPI DATAS REALIZADAS'!N:N,0,0,1) -> 46149 | F26: =_xlfn.XLOOKUP(D26,'COHVPI DATAS REALIZADAS'!C:C,'COHVPI DATAS REALIZADAS'!O:O,0,0,1) -> 46151 | G26: =_xlfn.XLOOKUP(D26,COHVPI!A:A,COHVPI!E:E,0,0,1) -> 14866 | H26: =_xlfn.XLOOKUP(D26,COHVPI!A:A,COHVPI!F:F,0,0,1) -> 15126 | I26: =H26/G26 -> 1.0174896 | L26: 27212-0 | M26: MONANGE DES ANTI FR VERMELHAS 12X200ML | N26: 5574.5 | O26: 5555 | P26: =O26/N26 -> 0.99650193 | R26: 17107-7 | S26: MONANGE DES ANTI SENSIVEL 12X90G NVF | T26: 14866 | U26: 14553 | V26: 0.97894524
A27: L53 | B27: 17425-5 | C27: BOZZANO DES ANTI ANTBAC FRESH 12X90G NVF | D27: 1960539 | E27: =_xlfn.XLOOKUP(D27,'COHVPI DATAS REALIZADAS'!C:C,'COHVPI DATAS REALIZADAS'!N:N,0,0,1) -> 46150 | F27: =_xlfn.XLOOKUP(D27,'COHVPI DATAS REALIZADAS'!C:C,'COHVPI DATAS REALIZADAS'!O:O,0,0,1) -> 46151 | G27: =_xlfn.XLOOKUP(D27,COHVPI!A:A,COHVPI!E:E,0,0,1) -> 14866 | H27: =_xlfn.XLOOKUP(D27,COHVPI!A:A,COHVPI!F:F,0,0,1) -> 14640 | I27: =H27/G27 -> 0.98479752 | L27: 27212-1 | M27: MONANGE DES ANTIT FR VM 12X200ML MT | N27: 27875 | O27: 27245 | P27: =O27/N27 -> 0.9773991 | R27: 17109-7 | S27: MONANGE DES ANTIT FL LAV 12X90G MT | T27: 104062 | U27: 101766 | V27: 0.97793623
A28: L53 | B28: 17425-5 | C28: BOZZANO DES ANTI ANTBAC FRESH 12X90G NVF | D28: 1962331 | E28: =_xlfn.XLOOKUP(D28,'COHVPI DATAS REALIZADAS'!C:C,'COHVPI DATAS REALIZADAS'!N:N,0,0,1) -> 46151 | F28: =_xlfn.XLOOKUP(D28,'COHVPI DATAS REALIZADAS'!C:C,'COHVPI DATAS REALIZADAS'!O:O,0,0,1) -> 46155 | G28: =_xlfn.XLOOKUP(D28,COHVPI!A:A,COHVPI!E:E,0,0,1) -> 22299 | H28: =_xlfn.XLOOKUP(D28,COHVPI!A:A,COHVPI!F:F,0,0,1) -> 21952 | I28: =H28/G28 -> 0.98443876 | L28: 27213-1 | M28: MONANGE DES ANTIT INVIS 12X200ML MT | N28: 11238 | O28: 11560 | P28: =O28/N28 -> 1.0286528 | R28: 27212-1 | S28: MONANGE DES ANTIT FR VM 12X200ML MT | T28: 27875 | U28: 27245 | V28: 0.9773991
A29: L53 | B29: 17425-5 | C29: BOZZANO DES ANTI ANTBAC FRESH 12X90G NVF | D29: 1962332 | E29: =_xlfn.XLOOKUP(D29,'COHVPI DATAS REALIZADAS'!C:C,'COHVPI DATAS REALIZADAS'!N:N,0,0,1) -> 46154 | F29: =_xlfn.XLOOKUP(D29,'COHVPI DATAS REALIZADAS'!C:C,'COHVPI DATAS REALIZADAS'!O:O,0,0,1) -> 46156 | G29: =_xlfn.XLOOKUP(D29,COHVPI!A:A,COHVPI!E:E,0,0,1) -> 14866 | H29: =_xlfn.XLOOKUP(D29,COHVPI!A:A,COHVPI!F:F,0,0,1) -> 14852 | I29: =H29/G29 -> 0.99905825 | L29: 27214-0 | M29: BOZZANO DES ANTI EXTREME SPORT 12X200ML | N29: 33450 | O29: 32974 | P29: =O29/N29 -> 0.98576981 | R29: 17111-6 | S29: MONANGE DES ANTI HIDR INTEN 12X90G NVF | T29: 14866 | U29: 14517 | V29: 0.97652361
A30: L53 | B30: 25004-1 | C30: BOZZANO DES ANTI CARVAO 12X90G NVF | D30: 1962333 | E30: =_xlfn.XLOOKUP(D30,'COHVPI DATAS REALIZADAS'!C:C,'COHVPI DATAS REALIZADAS'!N:N,0,0,1) -> 46156 | F30: =_xlfn.XLOOKUP(D30,'COHVPI DATAS REALIZADAS'!C:C,'COHVPI DATAS REALIZADAS'!O:O,0,0,1) -> 46157 | G30: =_xlfn.XLOOKUP(D30,COHVPI!A:A,COHVPI!E:E,0,0,1) -> 22299 | H30: =_xlfn.XLOOKUP(D30,COHVPI!A:A,COHVPI!F:F,0,0,1) -> 22080 | I30: =H30/G30 -> 0.99017893 | L30: 29553-0 | M30: BOZZANO DES ANTIT DRY 12X200ML | N30: 33450 | O30: 32935 | P30: =O30/N30 -> 0.98460389 | R30: 24631-2 | S30: MONANGE DES ANTIT PROT SEC 12X90G MT | T30: 66897 | U30: 65121 | V30: 0.97345172
A31: L53 | B31: 25004-1 | C31: BOZZANO DES ANTI CARVAO 12X90G NVF | D31: 1962334 | E31: =_xlfn.XLOOKUP(D31,'COHVPI DATAS REALIZADAS'!C:C,'COHVPI DATAS REALIZADAS'!N:N,0,0,1) -> 46157 | F31: =_xlfn.XLOOKUP(D31,'COHVPI DATAS REALIZADAS'!C:C,'COHVPI DATAS REALIZADAS'!O:O,0,0,1) -> 46159 | G31: =_xlfn.XLOOKUP(D31,COHVPI!A:A,COHVPI!E:E,0,0,1) -> 14866 | H31: =_xlfn.XLOOKUP(D31,COHVPI!A:A,COHVPI!F:F,0,0,1) -> 14400 | I31: =H31/G31 -> 0.9686533 | L31: 29554-0 | M31: BOZZANO DES ANTIT ANTIBAC FRESH 12X200ML | N31: 44600 | O31: 44460 | P31: =O31/N31 -> 0.99686099 | R31: 10909-3 | S31: BOZZANO ESPUMA BARBA REFRES 6X193G CIN | T31: 13330 | U31: 12971 | V31: 0.97306827
A32: L53 | B32: 25004-1 | C32: BOZZANO DES ANTI CARVAO 12X90G NVF | D32: 1962335 | E32: =_xlfn.XLOOKUP(D32,'COHVPI DATAS REALIZADAS'!C:C,'COHVPI DATAS REALIZADAS'!N:N,0,0,1) -> 46159 | F32: =_xlfn.XLOOKUP(D32,'COHVPI DATAS REALIZADAS'!C:C,'COHVPI DATAS REALIZADAS'!O:O,0,0,1) -> 46161 | G32: =_xlfn.XLOOKUP(D32,COHVPI!A:A,COHVPI!E:E,0,0,1) -> 14866 | H32: =_xlfn.XLOOKUP(D32,COHVPI!A:A,COHVPI!F:F,0,0,1) -> 14842 | I32: =H32/G32 -> 0.99838558 | L32: 29555-1 | M32: MONANGE DES ANTIT PROT SEC 12X200ML MT | N32: 11150 | O32: 10931 | P32: =O32/N32 -> 0.98035874 | R32: 25003-1 | S32: BOZZANO DES ANTI DRY 12X90G NVF | T32: 7433 | U32: 7229 | V32: 0.97255482
A33: L53 | B33: 13441-6 | C33: BOZZANO DES ANTI S PERF SENS 12X90G NVF | D33: 1962336 | E33: =_xlfn.XLOOKUP(D33,'COHVPI DATAS REALIZADAS'!C:C,'COHVPI DATAS REALIZADAS'!N:N,0,0,1) -> 46161 | F33: =_xlfn.XLOOKUP(D33,'COHVPI DATAS REALIZADAS'!C:C,'COHVPI DATAS REALIZADAS'!O:O,0,0,1) -> 46163 | G33: =_xlfn.XLOOKUP(D33,COHVPI!A:A,COHVPI!E:E,0,0,1) -> 21237 | H33: =_xlfn.XLOOKUP(D33,COHVPI!A:A,COHVPI!F:F,0,0,1) -> 22010 | I33: =H33/G33 -> 1.0363987 | L33: 8627-4 | M33: TRES MARCHAND DES ANTI CLASS 12X90G NVF | N33: 6457 | O33: 7132 | P33: =O33/N33 -> 1.1045377 | R33: 25644-0 | S33: BOZZANO CLINICAL CLEAN AERO 12X94G | T33: 8488 | U33: 8160 | V33: 0.96135721
A34: L53 | B34: 25003-1 | C34: BOZZANO DES ANTI DRY 12X90G NVF | D34: 1962770 | E34: =_xlfn.XLOOKUP(D34,'COHVPI DATAS REALIZADAS'!C:C,'COHVPI DATAS REALIZADAS'!N:N,0,0,1) -> 46163 | F34: =_xlfn.XLOOKUP(D34,'COHVPI DATAS REALIZADAS'!C:C,'COHVPI DATAS REALIZADAS'!O:O,0,0,1) -> 46164 | G34: =_xlfn.XLOOKUP(D34,COHVPI!A:A,COHVPI!E:E,0,0,1) -> 7433 | H34: =_xlfn.XLOOKUP(D34,COHVPI!A:A,COHVPI!F:F,0,0,1) -> 7229 | I34: =H34/G34 -> 0.97255482 | L34: Total Geral | N34: 1209384.5 | O34: 1206754 | P34: =O34/N34 -> 0.99782493 | R34: Total Geral | T34: 1209384.5 | U34: 1206754 | V34: 0.99782493
A35: L53 | B35: 25645-0 | C35: BOZZANO CLINIC ULTRA COOL AERO 12X94G | D35: 1962340 | E35: =_xlfn.XLOOKUP(D35,'COHVPI DATAS REALIZADAS'!C:C,'COHVPI DATAS REALIZADAS'!N:N,0,0,1) -> 46164 | F35: =_xlfn.XLOOKUP(D35,'COHVPI DATAS REALIZADAS'!C:C,'COHVPI DATAS REALIZADAS'!O:O,0,0,1) -> 46165 | G35: =_xlfn.XLOOKUP(D35,COHVPI!A:A,COHVPI!E:E,0,0,1) -> 8488 | H35: =_xlfn.XLOOKUP(D35,COHVPI!A:A,COHVPI!F:F,0,0,1) -> 8457 | I35: =H35/G35 -> 0.99634779
A36: L53 | B36: 17111-7 | C36: MONANGE DES ANTIT HIDR INTEN 12X90G MT | D36: 1962764 | E36: =_xlfn.XLOOKUP(D36,'COHVPI DATAS REALIZADAS'!C:C,'COHVPI DATAS REALIZADAS'!N:N,0,0,1) -> 46165 | F36: =_xlfn.XLOOKUP(D36,'COHVPI DATAS REALIZADAS'!C:C,'COHVPI DATAS REALIZADAS'!O:O,0,0,1) -> 46168 | G36: =_xlfn.XLOOKUP(D36,COHVPI!A:A,COHVPI!E:E,0,0,1) -> 14866 | H36: =_xlfn.XLOOKUP(D36,COHVPI!A:A,COHVPI!F:F,0,0,1) -> 14321 | I36: =H36/G36 -> 0.96333916
A37: L53 | B37: 17111-7 | C37: MONANGE DES ANTIT HIDR INTEN 12X90G MT | D37: 1962765 | E37: =_xlfn.XLOOKUP(D37,'COHVPI DATAS REALIZADAS'!C:C,'COHVPI DATAS REALIZADAS'!N:N,0,0,1) -> 46168 | F37: =_xlfn.XLOOKUP(D37,'COHVPI DATAS REALIZADAS'!C:C,'COHVPI DATAS REALIZADAS'!O:O,0,0,1) -> 46169 | G37: =_xlfn.XLOOKUP(D37,COHVPI!A:A,COHVPI!E:E,0,0,1) -> 14866 | H37: =_xlfn.XLOOKUP(D37,COHVPI!A:A,COHVPI!F:F,0,0,1) -> 14584 | I37: =H37/G37 -> 0.98103054
A38: L53 | B38: 24630-2 | C38: MONANGE DES ANTIT DETOX FRESH 12X90G MT | D38: 1963817 | E38: =_xlfn.XLOOKUP(D38,'COHVPI DATAS REALIZADAS'!C:C,'COHVPI DATAS REALIZADAS'!N:N,0,0,1) -> 46169 | F38: =_xlfn.XLOOKUP(D38,'COHVPI DATAS REALIZADAS'!C:C,'COHVPI DATAS REALIZADAS'!O:O,0,0,1) -> 46170 | G38: =_xlfn.XLOOKUP(D38,COHVPI!A:A,COHVPI!E:E,0,0,1) -> 7433 | H38: =_xlfn.XLOOKUP(D38,COHVPI!A:A,COHVPI!F:F,0,0,1) -> 7311 | I38: =H38/G38 -> 0.98358671
A39: L53 | B39: 23209-5 | C39: ADIDAS DES ANTI PRO INVISIBLE MASC 150ML | D39: 1962342 | E39: =_xlfn.XLOOKUP(D39,'COHVPI DATAS REALIZADAS'!C:C,'COHVPI DATAS REALIZADAS'!N:N,0,0,1) -> 46170 | F39: =_xlfn.XLOOKUP(D39,'COHVPI DATAS REALIZADAS'!C:C,'COHVPI DATAS REALIZADAS'!O:O,0,0,1) -> 46172 | G39: =_xlfn.XLOOKUP(D39,COHVPI!A:A,COHVPI!E:E,0,0,1) -> 15026 | H39: =_xlfn.XLOOKUP(D39,COHVPI!A:A,COHVPI!F:F,0,0,1) -> 14980 | I39: =H39/G39 -> 0.99693864
A40: TOTAL L53 | G40: =SUM(G22:G39) -> 245088 | H40: =SUM(H22:H39) -> 242976 | I40: =H40/G40 -> 0.99138269
A41: L57 | B41: 29554-0 | C41: BOZZANO DES ANTIT ANTIBAC FRESH 12X200ML | D41: 1957946 | E41: =_xlfn.XLOOKUP(D41,'COHVPI DATAS REALIZADAS'!C:C,'COHVPI DATAS REALIZADAS'!N:N,0,0,1) -> 0 | F41: =_xlfn.XLOOKUP(D41,'COHVPI DATAS REALIZADAS'!C:C,'COHVPI DATAS REALIZADAS'!O:O,0,0,1) -> 0 | G41: =_xlfn.XLOOKUP(D41,COHVPI!A:A,COHVPI!E:E,0,0,1) -> 0 | H41: =_xlfn.XLOOKUP(D41,COHVPI!A:A,COHVPI!F:F,0,0,1) -> 0 | I41: =H41/G41 -> #DIV/0!
A42: L57 | B42: 29553-0 | C42: BOZZANO DES ANTIT DRY 12X200ML | D42: 1957965 | E42: =_xlfn.XLOOKUP(D42,'COHVPI DATAS REALIZADAS'!C:C,'COHVPI DATAS REALIZADAS'!N:N,0,0,1) -> 46143 | F42: =_xlfn.XLOOKUP(D42,'COHVPI DATAS REALIZADAS'!C:C,'COHVPI DATAS REALIZADAS'!O:O,0,0,1) -> 46146 | G42: =_xlfn.XLOOKUP(D42,COHVPI!A:A,COHVPI!E:E,0,0,1) -> 11150 | H42: =_xlfn.XLOOKUP(D42,COHVPI!A:A,COHVPI!F:F,0,0,1) -> 11160 | I42: =H42/G42 -> 1.0008969
A43: L57 | B43: 27211-1 | C43: MONANGE DES ANTIT HIDR INTEN 12X200ML MT | D43: 1957949 | E43: =_xlfn.XLOOKUP(D43,'COHVPI DATAS REALIZADAS'!C:C,'COHVPI DATAS REALIZADAS'!N:N,0,0,1) -> 46146 | F43: =_xlfn.XLOOKUP(D43,'COHVPI DATAS REALIZADAS'!C:C,'COHVPI DATAS REALIZADAS'!O:O,0,0,1) -> 46147 | G43: =_xlfn.XLOOKUP(D43,COHVPI!A:A,COHVPI!E:E,0,0,1) -> 11150 | H43: =_xlfn.XLOOKUP(D43,COHVPI!A:A,COHVPI!F:F,0,0,1) -> 11000 | I43: =H43/G43 -> 0.98654709
A44: L57 | B44: 27211-1 | C44: MONANGE DES ANTIT HIDR INTEN 12X200ML MT | D44: 1957953 | E44: =_xlfn.XLOOKUP(D44,'COHVPI DATAS REALIZADAS'!C:C,'COHVPI DATAS REALIZADAS'!N:N,0,0,1) -> 46147 | F44: =_xlfn.XLOOKUP(D44,'COHVPI DATAS REALIZADAS'!C:C,'COHVPI DATAS REALIZADAS'!O:O,0,0,1) -> 46148 | G44: =_xlfn.XLOOKUP(D44,COHVPI!A:A,COHVPI!E:E,0,0,1) -> 11150 | H44: =_xlfn.XLOOKUP(D44,COHVPI!A:A,COHVPI!F:F,0,0,1) -> 11400 | I44: =H44/G44 -> 1.0224215
A45: L57 | B45: 27211-1 | C45: MONANGE DES ANTIT HIDR INTEN 12X200ML MT | D45: 1960551 | E45: =_xlfn.XLOOKUP(D45,'COHVPI DATAS REALIZADAS'!C:C,'COHVPI DATAS REALIZADAS'!N:N,0,0,1) -> 46148 | F45: =_xlfn.XLOOKUP(D45,'COHVPI DATAS REALIZADAS'!C:C,'COHVPI DATAS REALIZADAS'!O:O,0,0,1) -> 46150 | G45: =_xlfn.XLOOKUP(D45,COHVPI!A:A,COHVPI!E:E,0,0,1) -> 16725 | H45: =_xlfn.XLOOKUP(D45,COHVPI!A:A,COHVPI!F:F,0,0,1) -> 15800 | I45: =H45/G45 -> 0.94469357
...

Sheet Envase
B2: LINHA 40 AEROSSOL (FABRICAÇÃO 1000KG a 1200KG) | O2: =_xlfn.XLOOKUP(R2,PROCX!A:A,PROCX!H:H,"-",0,1) -> - | P2: LINHA 40 ENVASE AEROSSOL
B3: ORDEM | C3: LOTE | D3: QTD (KG) | E3: QTD | F3: CÓDIGO | G3: DESCRIÇÃO S.A | H3: Data Congelada | I3: DATA ENVASE | J3: A | K3: B | L3: C | M3: STATUS | O3: =_xlfn.XLOOKUP(R3,PROCX!A:A,PROCX!H:H,"-",0,1) -> UM básica (=EINHEIT) | P3: CÓDIGO | Q3: DESCRIÇÃO P.A | R3: ORDEM | S3: LINHA | T3: QTD Produzida (CX) | U3: QTD Programada (CX) | V3: QTD SAP (CX) | W3: RENDIMENTO (%) | X3: QTD (UN) | Y3: Obs
B4: 1957843 | C4: T26C1875 | D4: 1200 | F4: 466770 | G4: SA MONANGE DES ANTI INVISIVEL FRAG RET | I4: 46127 | M4: - | O4: =_xlfn.XLOOKUP(R4,PROCX!A:A,PROCX!H:H,"-",0,1) -> - | P4: 20257-3 | Q4: MONANGE DES ANTI INVISIVEL 12X89G NVF | R4: 1957943 | S4: =_xlfn.XLOOKUP(R4,'VERSÃO DE PROD'!B:B,'VERSÃO DE PROD'!A:A,0,0,1) -> 0 | T4: =SUMIF(COHVPI!A:A,Envase!R4,COHVPI!F:F) -> 0 | U4: =X4/12 -> 15026 | W4: =T4/U4 -> 0 | X4: =90156*2 -> 180312 | Y4: OK
B5: 1957845 | C5: T26C1877 | D5: 1200 | F5: 466770 | G5: SA MONANGE DES ANTI INVISIVEL FRAG RET | I5: 46128 | M5: - | O5: =_xlfn.XLOOKUP(R5,PROCX!A:A,PROCX!H:H,"-",0,1) -> 0
B6: 1957813 | C6: T26C1845 | D6: 1200 | F6: 462830 | G6: SA MONANGE DES ANTI ESPORTE NVF | I6: 46128 | M6: FALTA VÁLVULA 468257 | O6: =_xlfn.XLOOKUP(R6,PROCX!A:A,PROCX!H:H,"-",0,1) -> - | P6: 25503-0 | Q6: MONANGE DES ANTI ESPORTE AERO 12X90G | R6: 1957928 | S6: =_xlfn.XLOOKUP(R6,'VERSÃO DE PROD'!B:B,'VERSÃO DE PROD'!A:A,0,0,1) -> 0 | T6: =SUMIF(COHVPI!A:A,Envase!R6,COHVPI!F:F) -> 0 | U6: =X6/12 -> 14158 | W6: =T6/U6 -> 0 | X6: =84948*2 -> 169896 | Y6: OK
B7: 1957814 | C7: T26C1846 | D7: 1200 | F7: 462830 | G7: SA MONANGE DES ANTI ESPORTE NVF | I7: 46129 | M7: FALTA VÁLVULA 468257 | O7: =_xlfn.XLOOKUP(R7,PROCX!A:A,PROCX!H:H,"-",0,1) -> 0
B8: 1957815 | C8: T26C1847 | D8: 1200 | F8: 462830 | G8: SA MONANGE DES ANTI ESPORTE NVF | I8: 46129 | M8: FALTA VÁLVULA 468257 | O8: =_xlfn.XLOOKUP(R8,PROCX!A:A,PROCX!H:H,"-",0,1) -> - | P8: 25503-0 | Q8: MONANGE DES ANTI ESPORTE AERO 12X90G | R8: 1957933 | S8: =_xlfn.XLOOKUP(R8,'VERSÃO DE PROD'!B:B,'VERSÃO DE PROD'!A:A,0,0,1) -> 0 | T8: =SUMIF(COHVPI!A:A,Envase!R8,COHVPI!F:F) -> 0 | U8: =X8/12 -> 14158 | W8: =T8/U8 -> 0 | X8: =84948*2 -> 169896 | Y8: OK
B9: 1957816 | C9: T26C1848 | D9: 1200 | F9: 462830 | G9: SA MONANGE DES ANTI ESPORTE NVF | I9: 46132 | M9: FALTA VÁLVULA 468257 E CAIXA 465371 | O9: =_xlfn.XLOOKUP(R9,PROCX!A:A,PROCX!H:H,"-",0,1) -> 0
B10: 1957817 | C10: T26C1849 | D10: 1200 | F10: 462830 | G10: SA MONANGE DES ANTI ESPORTE NVF | I10: 46132 | M10: FALTA VÁLVULA 468257 + CAIXA 465371 + TAMPA 453598 | O10: =_xlfn.XLOOKUP(R10,PROCX!A:A,PROCX!H:H,"-",0,1) -> - | P10: 25503-0 | Q10: MONANGE DES ANTI ESPORTE AERO 12X90G | R10: 1959151 | S10: =_xlfn.XLOOKUP(R10,'VERSÃO DE PROD'!B:B,'VERSÃO DE PROD'!A:A,0,0,1) -> 0 | T10: =SUMIF(COHVPI!A:A,Envase!R10,COHVPI!F:F) -> 0 | U10: =X10/12 -> 14158 | W10: =T10/U10 -> 0 | X10: =84948*2 -> 169896 | Y10: OK
B11: 1957818 | C11: T26C1850 | D11: 1200 | F11: 462830 | G11: SA MONANGE DES ANTI ESPORTE NVF | I11: 46133 | M11: FALTA VÁLVULA 468257 + CAIXA 465371 + TAMPA 453598 | O11: =_xlfn.XLOOKUP(R11,PROCX!A:A,PROCX!H:H,"-",0,1) -> 0
B12: 1957485 | C12: T26C1631 | D12: 1200 | F12: 462828 | G12: SA MONANGE DES ANTI DETOX FRESH NVF | I12: 46133 | M12: - | O12: =_xlfn.XLOOKUP(R12,PROCX!A:A,PROCX!H:H,"-",0,1) -> - | P12: 24630-1 | Q12: MONANGE DES ANTI DETOX FRESH 12X90G NVF | R12: 1957469 | S12: =_xlfn.XLOOKUP(R12,'VERSÃO DE PROD'!B:B,'VERSÃO DE PROD'!A:A,0,0,1) -> 0 | T12: =SUMIF(COHVPI!A:A,Envase!R12,COHVPI!F:F) -> 0 | U12: =X12/12 -> 22299 | W12: =T12/U12 -> 0 | X12: =89196*3 -> 267588 | Y12: OK
B13: 1957486 | C13: T26C1632 | D13: 1200 | F13: 462828 | G13: SA MONANGE DES ANTI DETOX FRESH NVF | I13: 46133 | M13: - | O13: =_xlfn.XLOOKUP(R13,PROCX!A:A,PROCX!H:H,"-",0,1) -> 0
B14: 1957487 | C14: T26C1633 | D14: 1200 | F14: 462828 | G14: SA MONANGE DES ANTI DETOX FRESH NVF | I14: 46135 | M14: - | O14: =_xlfn.XLOOKUP(R14,PROCX!A:A,PROCX!H:H,"-",0,1) -> 0
B15: 1957807 | C15: T26C1839 | D15: 1200 | F15: 462828 | G15: SA MONANGE DES ANTI DETOX FRESH NVF | I15: 46135 | M15: - | O15: =_xlfn.XLOOKUP(R15,PROCX!A:A,PROCX!H:H,"-",0,1) -> - | P15: 24630-1 | Q15: MONANGE DES ANTI DETOX FRESH 12X90G NVF | R15: 1957951 | S15: =_xlfn.XLOOKUP(R15,'VERSÃO DE PROD'!B:B,'VERSÃO DE PROD'!A:A,0,0,1) -> 0 | T15: =SUMIF(COHVPI!A:A,Envase!R15,COHVPI!F:F) -> 0 | U15: =X15/12 -> 14866 | W15: =T15/U15 -> 0 | X15: =89196*2 -> 178392 | Y15: OK
B16: 1957809 | C16: T26C1841 | D16: 1200 | F16: 462828 | G16: SA MONANGE DES ANTI DETOX FRESH NVF | I16: 46136 | M16: - | O16: =_xlfn.XLOOKUP(R16,PROCX!A:A,PROCX!H:H,"-",0,1) -> 0
B17: 1957810 | C17: T26C1842 | D17: 1200 | F17: 462828 | G17: SA MONANGE DES ANTI DETOX FRESH NVF | I17: 46136 | M17: - | O17: =_xlfn.XLOOKUP(R17,PROCX!A:A,PROCX!H:H,"-",0,1) -> - | P17: 24630-1 | Q17: MONANGE DES ANTI DETOX FRESH 12X90G NVF | R17: 1957956 | S17: =_xlfn.XLOOKUP(R17,'VERSÃO DE PROD'!B:B,'VERSÃO DE PROD'!A:A,0,0,1) -> 0 | T17: =SUMIF(COHVPI!A:A,Envase!R17,COHVPI!F:F) -> 0 | U17: =X17/12 -> 14866 | W17: =T17/U17 -> 0 | X17: =89196*2 -> 178392 | Y17: OK
B18: 1957811 | C18: T26C1843 | D18: 1200 | F18: 462828 | G18: SA MONANGE DES ANTI DETOX FRESH NVF | H18: 46139 | I18: 46139 | M18: - | O18: =_xlfn.XLOOKUP(R18,PROCX!A:A,PROCX!H:H,"-",0,1) -> 0
B19: SETUP | O19: =_xlfn.XLOOKUP(R19,PROCX!A:A,PROCX!H:H,"-",0,1) -> 0 | P19: SETUP
B20: RISCO DE PARADA - FALTA DE TAMPA 453598 | O20: =_xlfn.XLOOKUP(R20,PROCX!A:A,PROCX!H:H,"-",0,1) -> 0 | P20: RISCO DE PARADA - FALTA DE TAMPA 453598
B21: 1957895 | C21: T26C1927 | D21: 1200 | F21: 469970 | G21: SA MONANGE DES ANTIT INVISIVEL TCP | H21: 46139 | I21: 46139 | M21: - | O21: =_xlfn.XLOOKUP(R21,PROCX!A:A,PROCX!H:H,"-",0,1) -> - | P21: 20257-4 | Q21: MONANGE DES ANTIT INVISL 12X89G MT | R21: 1957961 | S21: =_xlfn.XLOOKUP(R21,'VERSÃO DE PROD'!B:B,'VERSÃO DE PROD'!A:A,0,0,1) -> 0 | T21: =SUMIF(COHVPI!A:A,Envase!R21,COHVPI!F:F) -> 0 | U21: =X21/12 -> 15026 | W21: =T21/U21 -> 0 | X21: =90156*2 -> 180312 | Y21: PHASE IN - PROJETO MONTANA
B22: 1957896 | C22: T26C1928 | D22: 1200 | F22: 469970 | G22: SA MONANGE DES ANTIT INVISIVEL TCP | H22: 46140 | I22: 46139 | M22: - | O22: =_xlfn.XLOOKUP(R22,PROCX!A:A,PROCX!H:H,"-",0,1) -> 0
B23: 1957897 | C23: T26C1929 | D23: 1200 | E23: =_xlfn.XLOOKUP(B23,'VERSÃO DE PROD'!B:B,'VERSÃO DE PROD'!H:H,0,0,1) -> 0 | F23: 469970 | G23: SA MONANGE DES ANTIT INVISIVEL TCP | H23: 46140 | I23: 46140 | M23: - | O23: =_xlfn.XLOOKUP(R23,PROCX!A:A,PROCX!H:H,"-",0,1) -> - | P23: 20257-4 | Q23: MONANGE DES ANTIT INVISL 12X89G MT | R23: 1957967 | S23: =_xlfn.XLOOKUP(R23,'VERSÃO DE PROD'!B:B,'VERSÃO DE PROD'!A:A,0,0,1) -> 0 | T23: =SUMIF(COHVPI!A:A,Envase!R23,COHVPI!F:F) -> 0 | U23: =X23/12 -> 15026 | W23: =T23/U23 -> 0 | X23: =90156*2 -> 180312 | Y23: PHASE IN - PROJETO MONTANA
B24: 1957898 | C24: T26C1930 | D24: 1200 | E24: =_xlfn.XLOOKUP(B24,'VERSÃO DE PROD'!B:B,'VERSÃO DE PROD'!H:H,0,0,1) -> 0 | F24: 469970 | G24: SA MONANGE DES ANTIT INVISIVEL TCP | H24: 46141 | I24: 46142 | M24: - | O24: =_xlfn.XLOOKUP(R24,PROCX!A:A,PROCX!H:H,"-",0,1) -> 0
B25: 1960328 | C25: T26D0859 | D25: 1000 | E25: =_xlfn.XLOOKUP(B25,'VERSÃO DE PROD'!B:B,'VERSÃO DE PROD'!H:H,0,0,1) -> 0 | F25: 469964 | G25: SA MONANGE CLINICAL REVIGORANTE TCP | H25: 46141 | I25: 46142 | M25: OP FABRICAÇÃO COM 1200KG -> FALTA TUBO 470229 (EXTERNO) | O25: =_xlfn.XLOOKUP(R25,PROCX!A:A,PROCX!H:H,"-",0,1) -> - | P25: 25643-2 | Q25: MONANGE CLIN REVIG AERO 12X94G MT | R25: 1960517 | S25: =_xlfn.XLOOKUP(R25,'VERSÃO DE PROD'!B:B,'VERSÃO DE PROD'!A:A,0,0,1) -> 0 | T25: =SUMIF(COHVPI!A:A,Envase!R25,COHVPI!F:F) -> 0 | U25: =X25/12 -> 8488 | W25: =T25/U25 -> 0 | X25: 101856 | Y25: DEMANDA BAIXA E ALTA COBERTURA (MAIS DE 60 DIAS)
B26: 1961051 | C26: T26D1324 | D26: 1000 | E26: =_xlfn.XLOOKUP(B26,'VERSÃO DE PROD'!B:B,'VERSÃO DE PROD'!H:H,0,0,1) -> 0 | F26: 469964 | G26: SA MONANGE CLINICAL REVIGORANTE TCP | H26: 46141 | I26: 46142 | M26: OP FABRICAÇÃO COM 1200KG -> FALTA TUBO 470229 (EXTERNO) | O26: =_xlfn.XLOOKUP(R26,PROCX!A:A,PROCX!H:H,"-",0,1) -> 0
B27: 1960360 | C27: T26D0887 | D27: 1000 | E27: =_xlfn.XLOOKUP(B27,'VERSÃO DE PROD'!B:B,'VERSÃO DE PROD'!H:H,0,0,1) -> 0 | F27: 461828 | G27: SA BOZZANO CLINICAL CLEAN AERO | H27: 46142 | I27: 46142 | M27: - | O27: =_xlfn.XLOOKUP(R27,PROCX!A:A,PROCX!H:H,"-",0,1) -> - | P27: 25644-0 | Q27: BOZZANO CLINICAL CLEAN AERO 12X94G | R27: 1960536 | S27: =_xlfn.XLOOKUP(R27,'VERSÃO DE PROD'!B:B,'VERSÃO DE PROD'!A:A,0,0,1) -> 0 | T27: =SUMIF(COHVPI!A:A,Envase!R27,COHVPI!F:F) -> 8160 | U27: =X27/12 -> 8488 | W27: =T27/U27 -> 0.96135721 | X27: =50928*2 -> 101856 | Y27: DEMANDA BAIXA E ALTA COBERTURA (MAIS DE 60 DIAS)
B28: 1960361 | C28: T26D0888 | D28: 1000 | E28: =_xlfn.XLOOKUP(B28,'VERSÃO DE PROD'!B:B,'VERSÃO DE PROD'!H:H,0,0,1) -> 0 | F28: 461828 | G28: SA BOZZANO CLINICAL CLEAN AERO | H28: 46143 | I28: 46143 | M28: - | O28: =_xlfn.XLOOKUP(R28,PROCX!A:A,PROCX!H:H,"-",0,1) -> 0
B29: 1959062 | C29: T26C2686 | D29: 1200 | E29: =_xlfn.XLOOKUP(B29,'VERSÃO DE PROD'!B:B,'VERSÃO DE PROD'!H:H,0,0,1) -> 0 | F29: 462834 | G29: SA TRES MARCHAND DES ANTI CLASS NVF | H29: 46143 | I29: 46146 | M29: - | O29: =_xlfn.XLOOKUP(R29,PROCX!A:A,PROCX!H:H,"-",0,1) -> - | P29: 8627-4 | Q29: TRES MARCHAND DES ANTI CLASS 12X90G NVF | R29: 1959059 | S29: =_xlfn.XLOOKUP(R29,'VERSÃO DE PROD'!B:B,'VERSÃO DE PROD'!A:A,0,0,1) -> 0 | T29: =SUMIF(COHVPI!A:A,Envase!R29,COHVPI!F:F) -> 7132 | U29: =X29/12 -> 6457 | W29: =T29/U29 -> 1.1045377 | X29: 77484 | Y29: DEMANDA BAIXA E ALTA COBERTURA (MAIS DE 60 DIAS)
B30: 1960325 | C30: T26D0857 | D30: 1200 | E30: =_xlfn.XLOOKUP(B30,'VERSÃO DE PROD'!B:B,'VERSÃO DE PROD'!H:H,0,0,1) -> 0 | F30: 469971 | G30: SA MONANGE DES ANTIT PROT SECA TCP | H30: 46146 | I30: 46146 | M30: - | O30: =_xlfn.XLOOKUP(R30,PROCX!A:A,PROCX!H:H,"-",0,1) -> - | P30: 24631-2 | Q30: MONANGE DES ANTIT PROT SEC 12X90G MT | R30: 1960792 | S30: =_xlfn.XLOOKUP(R30,'VERSÃO DE PROD'!B:B,'VERSÃO DE PROD'!A:A,0,0,1) -> 0 | T30: =SUMIF(COHVPI!A:A,Envase!R30,COHVPI!F:F) -> 21600 | U30: =X30/12 -> 22299 | W30: =T30/U30 -> 0.9686533 | X30: =89196*3 -> 267588 | Y30: OK
B31: 1960793 | C31: T26D1155 | D31: 1200 | E31: =_xlfn.XLOOKUP(B31,'VERSÃO DE PROD'!B:B,'VERSÃO DE PROD'!H:H,0,0,1) -> 0 | F31: 469971 | G31: SA MONANGE DES ANTIT PROT SECA TCP | H31: 46146 | I31: 46146 | M31: - | O31: =_xlfn.XLOOKUP(R31,PROCX!A:A,PROCX!H:H,"-",0,1) -> 0
B32: 1960794 | C32: T26D1156 | D32: 1200 | E32: =_xlfn.XLOOKUP(B32,'VERSÃO DE PROD'!B:B,'VERSÃO DE PROD'!H:H,0,0,1) -> 0 | F32: 469971 | G32: SA MONANGE DES ANTIT PROT SECA TCP | H32: 46148 | I32: 46148 | M32: - | O32: =_xlfn.XLOOKUP(R32,PROCX!A:A,PROCX!H:H,"-",0,1) -> 0
B33: 1960319 | C33: T26D0851 | D33: 1200 | E33: =_xlfn.XLOOKUP(B33,'VERSÃO DE PROD'!B:B,'VERSÃO DE PROD'!H:H,0,0,1) -> 0 | F33: 469971 | G33: SA MONANGE DES ANTIT PROT SECA TCP | H33: 46148 | I33: 46148 | M33: - | O33: =_xlfn.XLOOKUP(R33,PROCX!A:A,PROCX!H:H,"-",0,1) -> - | P33: 24631-2 | Q33: MONANGE DES ANTIT PROT SEC 12X90G MT | R33: 1960789 | S33: =_xlfn.XLOOKUP(R33,'VERSÃO DE PROD'!B:B,'VERSÃO DE PROD'!A:A,0,0,1) -> 0 | T33: =SUMIF(COHVPI!A:A,Envase!R33,COHVPI!F:F) -> 14160 | U33: =X33/12 -> 14866 | W33: =T33/U33 -> 0.95250908 | X33: =89196*2 -> 178392 | Y33: OK
B34: 1960320 | C34: T26D0852 | D34: 1200 | E34: =_xlfn.XLOOKUP(B34,'VERSÃO DE PROD'!B:B,'VERSÃO DE PROD'!H:H,0,0,1) -> 0 | F34: 469971 | G34: SA MONANGE DES ANTIT PROT SECA TCP | H34: 46149 | I34: 46150 | M34: - | O34: =_xlfn.XLOOKUP(R34,PROCX!A:A,PROCX!H:H,"-",0,1) -> 0
B35: 1960321 | C35: T26D0853 | D35: 1200 | E35: =_xlfn.XLOOKUP(B35,'VERSÃO DE PROD'!B:B,'VERSÃO DE PROD'!H:H,0,0,1) -> 0 | F35: 469971 | G35: SA MONANGE DES ANTIT PROT SECA TCP | H35: 46149 | I35: 46150 | M35: - | O35: =_xlfn.XLOOKUP(R35,PROCX!A:A,PROCX!H:H,"-",0,1) -> - | P35: 24631-2 | Q35: MONANGE DES ANTIT PROT SEC 12X90G MT | R35: 1960790 | S35: =_xlfn.XLOOKUP(R35,'VERSÃO DE PROD'!B:B,'VERSÃO DE PROD'!A:A,0,0,1) -> 0 | T35: =SUMIF(COHVPI!A:A,Envase!R35,COHVPI!F:F) -> 14640 | U35: =X35/12 -> 14866 | W35: =T35/U35 -> 0.98479752 | X35: =89196*2 -> 178392 | Y35: OK
B36: 1960322 | C36: T26D0854 | D36: 1200 | E36: =_xlfn.XLOOKUP(B36,'VERSÃO DE PROD'!B:B,'VERSÃO DE PROD'!H:H,0,0,1) -> 0 | F36: 469971 | G36: SA MONANGE DES ANTIT PROT SECA TCP | H36: 46150 | I36: 46151 | M36: - | O36: =_xlfn.XLOOKUP(R36,PROCX!A:A,PROCX!H:H,"-",0,1) -> 0
B37: 1960323 | C37: T26D0855 | D37: 1200 | E37: =_xlfn.XLOOKUP(B37,'VERSÃO DE PROD'!B:B,'VERSÃO DE PROD'!H:H,0,0,1) -> 0 | F37: 469971 | G37: SA MONANGE DES ANTIT PROT SECA TCP | H37: 46150 | I37: 46151 | M37: - | O37: =_xlfn.XLOOKUP(R37,PROCX!A:A,PROCX!H:H,"-",0,1) -> - | P37: 24631-2 | Q37: MONANGE DES ANTIT PROT SEC 12X90G MT | R37: 1960791 | S37: =_xlfn.XLOOKUP(R37,'VERSÃO DE PROD'!B:B,'VERSÃO DE PROD'!A:A,0,0,1) -> 0 | T37: =SUMIF(COHVPI!A:A,Envase!R37,COHVPI!F:F) -> 14721 | U37: =X37/12 -> 14866 | W37: =T37/U37 -> 0.9902462 | X37: =89196*2 -> 178392 | Y37: OK
B38: 1960324 | C38: T26D0856 | D38: 1200 | E38: =_xlfn.XLOOKUP(B38,'VERSÃO DE PROD'!B:B,'VERSÃO DE PROD'!H:H,0,0,1) -> 0 | F38: 469971 | G38: SA MONANGE DES ANTIT PROT SECA TCP | H38: 46153 | I38: 46153 | M38: - | O38: =_xlfn.XLOOKUP(R38,PROCX!A:A,PROCX!H:H,"-",0,1) -> 0
B39: SETUP | O39: =_xlfn.XLOOKUP(R39,PROCX!A:A,PROCX!H:H,"-",0,1) -> 0 | P39: SETUP
B40: 1962559 | C40: T26E0344 | D40: 1200 | E40: =_xlfn.XLOOKUP(B40,COHVPI!A:A,COHVPI!E:E,0,0,1) -> 1200 | F40: 462824 | G40: SA MONANGE DES ANTI FLOR LAV NVF | I40: 46153 | M40: - | O40: =_xlfn.XLOOKUP(R40,PROCX!A:A,PROCX!H:H,"-",0,1) -> - | P40: 17109-6 | Q40: MONANGE DES ANTI FLOR LAV 12X90G NVF | R40: 1962558 | S40: =_xlfn.XLOOKUP(R40,'VERSÃO DE PROD'!B:B,'VERSÃO DE PROD'!A:A,0,0,1) -> 0 | T40: =SUMIF(COHVPI!A:A,Envase!R40,COHVPI!F:F) -> 14628 | U40: =X40/12 -> 14866 | W40: =T40/U40 -> 0.98399031 | X40: 178392 | Y40: ESGOTAMENTO (PHASE OUT) - PROJETO MONTANA
B41: 1962560 | C41: T26E0345 | D41: 1200 | E41: =_xlfn.XLOOKUP(B41,COHVPI!A:A,COHVPI!E:E,0,0,1) -> 1200 | F41: 462824 | G41: SA MONANGE DES ANTI FLOR LAV NVF | I41: 46154 | M41: - | N41: 17107-7 | O41: =_xlfn.XLOOKUP(R41,PROCX!A:A,PROCX!H:H,"-",0,1) -> 0
...

Sheet Planilha1
H1: Saldo de tubos
A2: Codigo | B2: Descrição | C2: Conversor | D2: Projeto | E2: Falta Produzir Ajustado MOQ | F2: Data Programada | G2: Qtd Programada (UN) | H2: Código Tubo | I2: Dep. 1000 | J2: CQ | K2: TRIVIUM | L2: Tubos em estoque + terceiros (UN) | M2: Sobra de tubos (UN)
A3: 25642-1 | B3: MONANGE CLINICAL CONFORTO AERO 12X94G NL | C3: 12 | D3: MONTANA | E3: 50928 | F3: 46176 | G3: 50928 | H3: 468382 | I3: 57753 | L3: 57753 | M3: 6825
A4: 27213-0 | B4: MONANGE DES ANTI INVISIVEL 12X200ML | C4: 12 | D4: MONTANA | E4: 67423 | F4: 46182 | G4: 67428 | H4: 465466 | I4: 71982 | L4: 71982 | M4: 4554
A5: 17109-6 | B5: MONANGE DES ANTI FLOR LAV 12X90G NVF | C5: 12 | D5: MONTANA | E5: 89196 | F5: 46182 | G5: 89196 | H5: 462803 | I5: 4304 | K5: 85932 | L5: 90236 | M5: 1040
A6: 17110-7 | B6: MONANGE DES ANTI FRUTAS VM 12X90G NVF | C6: 12 | D6: MONTANA | E6: 89196 | F6: 46181 | G6: 89196 | H6: 462804 | I6: 39060 | K6: 53568 | L6: 92628 | M6: 3432
A7: 24630-1 | B7: MONANGE DES ANTI DETOX FRESH 12X90G NVF | C7: 12 | D7: MONTANA | E7: 89196 | F7: 46177 | G7: 89196 | H7: 462807 | I7: 46686 | J7: 43431 | L7: 90117 | M7: 921
A8: 17107-7 | B8: MONANGE DES ANTI SENSIVEL 12X90G NVF | C8: 12 | D8: MONTANA | E8: 89196 | F8: 46183 | G8: 89196 | H8: 462802 | I8: 14973 | K8: 79794 | L8: 94767 | M8: 5571
A9: 20257-3 | B9: MONANGE DES ANTI INVISIVEL 12X89G NVF | C9: 12 | D9: MONTANA | E9: 90153 | F9: 46178 | G9: 90156 | H9: 462806 | I9: 35486 | K9: 61380 | L9: 96866 | M9: 6710
A10: 27170-0 | B10: ADIDAS DES ANTI POWER BOOSTER FEM 150ML | C10: 12 | D10: REVAMP | E10: 254844 | F10: 46185 | G10: 234072 | H10: 465340 | I10: 166377 | J10: 74772 | L10: 241149 | M10: 7077
A11: 27172-0 | B11: ADIDAS DES ANTI POWER BOOSTER MASC 12X90G | C11: 12 | D11: REVAMP | E11: 84948 | F11: 46184 | G11: 89196 | H11: 465344 | I11: 90001 | L11: 90001 | M11: 805
A12: 27171-0 | B12: ADIDAS DES ANTI FRESH ENDURANCE FEM 12X90G | C12: 12 | D12: REVAMP | E12: 169896 | F12: Sem data definida | G12: 169896 | H12: 465341 | I12: 39060 | K12: 134260 | L12: 173320 | M12: 3424
A13: 20003-6 | B13: ADIDAS DES ANTI CONTROL FEM 12X90G NVF | C13: 12 | D13: REVAMP | E13: Finalizado | F13: - | G13: - | H13: 465342 | I13: 31155 | J13: 0 | L13: 31155 | M13: 31155
A14: 23208-2 | B14: ADIDAS DES ANTI INVISIBLE FEM 12X90G | C14: 12 | D14: REVAMP | E14: Finalizado | F14: - | G14: - | H14: 465339 | I14: 9686 | J14: 0 | L14: 9686 | M14: 9686
A15: 27173-0 | B15: ADIDAS DES ANTI FRESH ENDURANCE MASC 12X90G | C15: 12 | D15: REVAMP | E15: Finalizado | F15: - | G15: - | H15: 465345 | I15: 2232 | J15: 0 | L15: 2232 | M15: 2232
A16: 23209-3 | B16: ADIDAS DES ANTI INVISIBLE MASC 12X90G | C16: 12 | D16: REVAMP | E16: Finalizado | F16: - | G16: - | H16: 465343 | I16: 0 | J16: 0 | L16: 0 | M16: 0
A17: 27174-0 | B17: ADIDAS DES ANTI 6 IN 1 MASC 150ML | C17: 12 | D17: REVAMP | E17: Finalizado | F17: - | G17: - | H17: 465346 | I17: 1621 | J17: 0 | L17: 1621 | M17: 1621
A18: 17111-6 | B18: MONANGE DES ANTI HIDR INTEN 12X90G NVF | C18: 12 | D18: MONTANA | E18: Finalizado | F18: - | G18: - | H18: 465942 | I18: 27385 | J18: 0 | L18: 27385 | M18: 27385
A19: 24631-1 | B19: MONANGE DES ANTI PROTECAO SEC 12X90G NVF | C19: 12 | D19: MONTANA | E19: Finalizado | F19: - | G19: - | H19: 462808 | I19: 1959 | J19: 0 | L19: 1959 | M19: 1959
A20: 25503-0 | B20: MONANGE DES ANTI ESPORTE AERO 12X90G | C20: 12 | D20: MONTANA | E20: Finalizado | F20: - | G20: - | H20: 461763 | I20: 17391 | J20: 0 | L20: 17391 | M20: 17391
A21: 25643-1 | B21: MONANGE CLIN REVIGORANTE AERO 12X94G NL | C21: 12 | D21: MONTANA | E21: Finalizado | F21: - | G21: - | H21: 468381 | I21: 25428 | J21: 0 | L21: 25428 | M21: 25428
A22: 27211-0 | B22: MONANGE DES ANTI HIDR INTENSIVA 12X200ML | C22: 12 | D22: MONTANA | E22: Finalizado | F22: - | G22: - | H22: 465464 | I22: 11160 | J22: 0 | L22: 11160 | M22: 11160
A23: 27212-0 | B23: MONANGE DES ANTI FR VERMELHAS 12X200ML | C23: 12 | D23: MONTANA | E23: Finalizado | F23: - | G23: - | H23: 465465 | I23: 29907 | J23: 0 | L23: 29907 | M23: 29907
A24: 29555-0 | B24: MONANGE DES ANTIT PROTECAO SECA 12X200ML | C24: 12 | D24: MONTANA | E24: Finalizado | F24: - | G24: - | H24: 469541 | I24: 1850 | J24: 0 | L24: 1850 | M24: 1850
A25: 29556-0 | B25: MONANGE DES ANTIT FLOR DE LAV 12X200ML | C25: 12 | D25: MONTANA | E25: Finalizado | F25: - | G25: - | H25: 469542 | I25: 15624 | J25: 0 | L25: 15624 | M25: 15624

Sheet Acompanhamento Rupturas
A1: SKU | B1: Descrição | C1: Ruptura UG | D1: Ruptura GS | E1: Volume Programado | F1: Data | G1: Ranking | H1: Motivos | J1: 46168
A2: 27213-1 | B2: MONANGE DES ANTIT INVIS 12X200ML MT | C2: 104844 | D2: 840082.33 | E2: 404568 | F2: 09/06 a 15/06 | G2: 1 | H2: Fragrância chega dia 02/06 e primeira oportunidade de envase é dia 09/06
A3: 29552-0 | B3: BOZZANO DES ANTIT CARVAO ATIV 12X200ML | C3: 43344 | D3: 342627.66 | E3: 401400 | F3: 22/06 a 26/06 | G3: 2 | H3: Falta tampa 460851 - Se usar qtd que chega dia 27/05 na L57, teremos parada na L58
A4: 23209-5 | B4: ADIDAS DES ANTI PRO INVISIBLE MASC 150ML | C4: 28092 | D4: 230703.31 | E4: 180312 | F4: 28/05 a 29/05 | G4: 3 | H4: -
A5: 23208-4 | B5: ADIDAS DES ANTI CONTR INVISIBLE FEM 150M | C5: 25164 | D5: 197138.56 | E5: 171720 | F5: 29/05 a 30/05 | G5: 4 | H5: -
A6: 29030-0 | B6: ADIDAS DES ANTI CLINICAL CARE FEM 150ML | C6: 15492 | D6: 165354.29 | E6: 50928 | F6: 18/06 a 19/06 | G6: 5 | H6: Fragrância atrasou. Nova previsão de chegada: 15/06. Talvez haja reprogramação pro dia 19/06 por segurança
A7: 17110-7 | B7: MONANGE DES ANTI FRUTAS VM 12X90G NVF | C7: 17004 | D7: 128344.96 | E7: 89196 | F7: 08/06 a 09/06 | G7: 6 | H7: Tubo chega 03/06 - Linha rodando os Phase Out Monange. Possibilidade de inverter seq. com 20257-3
A8: 27170-0 | B8: ADIDAS DES ANTI POWER BOOSTER FEM 150ML | C8: 11988 | D8: 85913.402 | E8: 234072 | F8: 11/06 a 15/06 | G8: 7 | H8: Fragrância 465405 chega 02/06. Não programei envase para 06/06 para não quebrar sequência de marca
A9: 10909-3 | B9: BOZZANO ESPUMA BARBA REFRES 6X193G CIN | C9: 4260 | D9: 61469.295 | E9: 79980 | F9: 28/05 a 30/05 | G9: 8 | H9: -
A10: 20257-3 | B10: MONANGE DES ANTI INVISIVEL 12X89G NVF | C10: 5868 | D10: 42393.394 | E10: 90156 | F10: 05/06 a 08/06 | G10: 9 | H10: Tubo chega 03/06 - Linha rodando os Phase Out Monange
A11: 27213-0 | B11: MONANGE DES ANTI INVISIVEL 12X200ML | C11: 3516 | D11: 37498.481 | E11: 67428 | F11: 09/06 a 10/06 | G11: 10 | H11: Oportunidade (para não quebrar sequência de marca)
A12: 17111-6 | B12: MONANGE DES ANTI HIDR INTEN 12X90G NVF | C12: 4500 | D12: 32998.185 | E12: - | F12: Plano Finalizado | G12: 11 | H12: Plano Phase Out Finalizado
A13: 17109-6 | B13: MONANGE DES ANTI FLOR LAV 12X90G NVF | C13: 3600 | D13: 28102.551 | E13: 89196 | F13: 09/06 a 10/06 | G13: 12 | H13: Tubo chega 03/06 - Linha rodando os Phase Out Monange
A14: 27212-0 | B14: MONANGE DES ANTI FR VERMELHAS 12X200ML | C14: 1836 | D14: 21408.91 | E14: - | F14: Plano Finalizado | G14: 13 | H14: Plano Phase Out Finalizado
A15: 27172-0 | B15: ADIDAS DES ANTI POWER BOOSTER MASC 150ML | C15: 1248 | D15: 9014.2832 | E15: 89196 | F15: 30/05 a 02/06 | G15: 14 | H15: Fragrância atrasou - Programado para 30/05 ou 02/06
A16: 20003-6 | B16: ADIDAS DES ANTI CONTROL FEM 150ML NVF | C16: 528 | D16: 4520.12 | E16: - | F16: Ordem de retrabalho feita | G16: 15 | H16: Qualidade avaliando o retrabalho feito com esse P.A. (OP feita dia 22/05)
E17: =_xlfn.XLOOKUP(A17,$A$1:$A$16,$E$1:$E$16,0,0,1) -> 0 | F17: =_xlfn.XLOOKUP(A17,$A$1:$A$16,$F$1:$F$16,0,0,1) -> 0 | G17: 1 | H17: =_xlfn.XLOOKUP(A17,$A$1:$A$16,$H$1:$H$16,0,0,1) -> 0
A18: SKU | B18: Descrição | C18: Ruptura UG | D18: Ruptura GS | E18: Volume Programado | F18: Data | G18: Ranking | H18: Motivos | J18: 46169
A19: 29552-0 | B19: BOZZANO DES ANTIT CARVAO ATIV 12X200ML | C19: 81804 | D19: 701270.62 | E19: 401400 | F19: 22/06 a 26/06 | G19: 1 | H19: Falta tampa 460851 - Se usar qtd que chega dia 27/05 na L57, teremos parada na L58
A20: 23209-5 | B20: ADIDAS DES ANTI PRO INVISIBLE MASC 150ML | C20: 68928 | D20: 623242.14 | E20: 180312 | F20: 28/05 a 29/05 | G20: 2 | H20: -
A21: 27212-0 | B21: MONANGE DES ANTI FR VERMELHAS 12X200ML | C21: 52716 | D21: 476416.44 | E21: - | F21: Plano Finalizado | G21: 3 | H21: Plano Phase Out Finalizado
A22: 23208-4 | B22: ADIDAS DES ANTI CONTR INVISIBLE FEM 150M | C22: 41844 | D22: 354308.87 | E22: 171720 | F22: 29/05 a 30/05 | G22: 4 | H22: -
A23: 29030-0 | B23: ADIDAS DES ANTI CLINICAL CARE FEM 150ML | C23: 15624 | D23: 167570.13 | E23: 50928 | F23: 18/06 a 19/06 | G23: 5 | H23: Fragrância atrasou. Nova previsão de chegada: 15/06. Talvez haja reprogramação pro dia 19/06 por segurança
A24: 17110-7 | B24: MONANGE DES ANTI FRUTAS VM 12X90G NVF | C24: 17004 | D24: 128344.96 | E24: 89196 | F24: 08/06 a 09/06 | G24: 6 | H24: Tubo chega 03/06 - Linha rodando os Phase Out Monange. Possibilidade de inverter seq. com 20257-3
A25: 27170-0 | B25: ADIDAS DES ANTI POWER BOOSTER FEM 150ML | C25: 12540 | D25: 90152.778 | E25: 234072 | F25: 11/06 a 15/06 | G25: 7 | H25: Fragrância 465405 chega 02/06. Não programei envase para 06/06 para não quebrar sequência de marca
A26: 10909-3 | B26: BOZZANO ESPUMA BARBA REFRES 6X193G CIN | C26: 6582 | D26: 90043.06 | E26: 79980 | F26: 28/05 a 30/05 | G26: 8 | H26: -
A27: 27213-0 | B27: MONANGE DES ANTI INVISIVEL 12X200ML | C27: 5304 | D27: 54665.156 | E27: 67428 | F27: 09/06 a 10/06 | G27: 9 | H27: Oportunidade (para não quebrar sequência de marca)
A28: 25643-1 | B28: MONANGE CLIN REVIGORANTE AERO 12X94G NL | C28: 4908 | D28: 36186.146 | E28: - | F28: Plano Finalizado | G28: 10 | H28: Plano Phase Out Finalizado
A29: 27172-0 | B29: ADIDAS DES ANTI POWER BOOSTER MASC 150ML | C29: 3624 | D29: 28042.893 | E29: 89196 | F29: 30/05 a 02/06 | G29: 11 | H29: Fragrância atrasou - Programado para 30/05 ou 02/06
A30: 20003-6 | B30: ADIDAS DES ANTI CONTROL FEM 150ML NVF | C30: 528 | D30: 4520.12 | E30: - | F30: Ordem de retrabalho feita | G30: 12 | H30: Qualidade avaliando o retrabalho feito com esse P.A. (OP feita dia 22/05)
A32: SKU | B32: Descrição | C32: Ruptura UG | D32: Ruptura GS | E32: Volume Programado | F32: Data | G32: Ranking | H32: Motivos | J32: 46170
A33: 24631-1 | B33: MONANGE DES ANTI PROTECAO SEC 12X90G NVF | C33: 241164 | D33: 1423942.3 | E33: - | F33: Plano Finalizado | G33: 1 | H33: Plano Phase Out Finalizado
A34: 29552-0 | B34: BOZZANO DES ANTIT CARVAO ATIV 12X200ML | C34: 114228 | D34: 966540.92 | E34: 401400 | F34: 22/06 a 26/06 | G34: 2 | H34: Falta tampa 460851 - Se usar qtd que chega dia 27/05 na L57, teremos parada na L58
A35: 23209-5 | B35: ADIDAS DES ANTI PRO INVISIBLE MASC 150ML | C35: 105132 | D35: 924139.99 | E35: 180312 | F35: 28/05 a 29/05 | G35: 3 | H35: -
A36: 24630-1 | B36: MONANGE DES ANTI DETOX FRESH 12X90G NVF | C36: 148956 | D36: 888537.83 | E36: 89196 | F36: 04/06 a 05/06 | G36: 4 | H36: Ultima produção Phase Out Montana - Tubo chega 02/06
A37: 23208-4 | B37: ADIDAS DES ANTI CONTR INVISIBLE FEM 150M | C37: 64896 | D37: 555549.2 | E37: 171720 | F37: 29/05 a 30/05 | G37: 5 | H37: -
A38: 27212-0 | B38: MONANGE DES ANTI FR VERMELHAS 12X200ML | C38: 50748 | D38: 460495.57 | E38: - | F38: Plano Finalizado | G38: 6 | H38: Plano Phase Out Finalizado
A39: 27211-0 | B39: MONANGE DES ANTI HIDR INTENSIVA 12X200ML | C39: 53556 | D39: 397684.85 | E39: - | F39: Plano Finalizado | G39: 7 | H39: Plano Phase Out Finalizado
A40: 17109-7 | B40: MONANGE DES ANTIT FL LAV 12X90G MT | C40: 57012 | D40: 339318.29 | E40: 624732 | F40: 27/05 a 03/06 | G40: 8 | H40: Em campanha na L40
A41: 10909-3 | B41: BOZZANO ESPUMA BARBA REFRES 6X193G CIN | C41: 17010 | D41: 218309.21 | E41: 79980 | F41: 28/05 a 30/05 | G41: 9 | H41: -
...

Sheet PROCX
A1: Ordem | B1: Material | C1: Lista comp.item | D1: Requirement date | E1: Qtd.necessária (EINHEIT) | F1: Qtd.retirada (EINHEIT) | G1: Qtd.pendente (EINHEIT) | H1: UM básica (=EINHEIT)
A2: 1962360 | B2: 452602 | C2: 0050 | D2: 46176 | E2: 135467.71 | F2: 36144 | G2: 0 | H2: ok
A3: 1963469 | B3: 452602 | C3: 0050 | D3: 46176 | E3: 271549.87 | F3: 137323.1 | G3: 0 | H3: ok
A4: 1962361 | B4: 452602 | C4: 0050 | D4: 46178 | E4: 135467.71 | F4: 97757.472 | G4: 36000 | H4: ok
A5: 1963058 | B5: 452602 | C5: 0050 | D5: 46181 | E5: 135467.71 | F5: 0 | G5: 135467.71 | H5: ok
A6: 1963470 | B6: 452602 | C6: 0050 | D6: 46198 | E6: 271549.87 | F6: 0 | G6: 271549.87 | H6: import
A7: 1963493 | B7: 452602 | C7: 0050 | D7: 46203 | E7: 77793.936 | F7: 0 | G7: 77793.936 | H7: import
A8: 1964887 | B8: 452602 | C8: 0030 | D8: 46203 | E8: 51131.712 | F8: 0 | G8: 51131.712 | H8: import
G10: 42
G11: 660 | H11: dia 08

Sheet NPD + Esgotamentos
F2: =SUM(F4:F17) -> 1402202 | G2: =SUM(G4:G17) -> 602076 | H2: =SUM(H4:H17) -> 801377
B3: Motivo | C3: SKU | D3: Descrição | E3: Plano Pendente excl NPD | F3: Plano Pendente Dash NPD 28/04 | G3: Realizado entre 29 e 13/05 | H3: Plano Pendente Atualizado 13/05 | I3: Volume Próximo Envase | J3: Data Prev. Envase | K3: Obs
B4: Phase Out para Montana | C4: 25642-1 | D4: MONANGE CLINICAL CONFORTO AERO 12X94G NL | F4: =VLOOKUP(C4,'[4]Phase out '!$A:$G,7,0) -> 50928 | H4: =F4-G4 -> 50928 | I4: 50928 | J4: 46176 | K4: Tubo 468382 chega 02/06
B5: Phase Out para Montana | C5: 17110-7 | D5: MONANGE DES ANTI FRUTAS VM 12X90G NVF | F5: =VLOOKUP(C5,'[4]Phase out '!$A:$G,7,0) -> 89196 | H5: =F5-G5 -> 89196 | I5: 89196 | J5: 46181 | K5: Tubo 462804 chega 03/06
B6: Phase Out para Montana | C6: 24630-1 | D6: MONANGE DES ANTI DETOX FRESH 12X90G NVF | F6: =VLOOKUP(C6,'[4]Phase out '!$A:$G,7,0) -> 89196 | H6: =F6-G6 -> 89196 | I6: 89196 | J6: 46177 | K6: Tubo 462807 chega 03/06
B7: Phase Out para Montana | C7: 20257-3 | D7: MONANGE DES ANTI INVISIVEL 12X89G NVF | F7: 90153 | H7: =F7-G7 -> 90153 | I7: =180312/2 -> 90156 | J7: 46178 | K7: Tubo 462806 chega 03/06
B8: Phase Out para Montana | C8: 17107-7 | D8: MONANGE DES ANTI SENSIVEL 12X90G NVF | F8: =VLOOKUP(C8,'[4]Phase out '!$A:$G,7,0) -> 267588 | G8: 178392 | H8: =F8-G8 -> 89196 | I8: 89196 | J8: 46183 | K8: Tubo 462802 chega 04/06
B9: Phase Out para Montana | C9: 17109-6 | D9: MONANGE DES ANTI FLOR LAV 12X90G NVF | F9: =VLOOKUP(C9,'[4]Phase out '!$A:$G,7,0) -> 267588 | G9: 178392 | H9: =F9-G9 -> 89196 | I9: 89196 | J9: 46182 | K9: Tubo 462803 chega 04/06
B10: Phase Out para Montana | C10: 27212-0 | D10: MONANGE DES ANTI FR VERMELHAS 12X200ML | F10: =VLOOKUP(C10,'[4]Phase out '!$A:$G,7,0) -> 66894 | G10: 66900 | H10: =F10-G10 -> -6 | J10: - | K10: FINALIZADO
B11: Phase Out para Montana | C11: 17111-6 | D11: MONANGE DES ANTI HIDR INTEN 12X90G NVF | F11: =VLOOKUP(C11,'[4]Phase out '!$A:$G,7,0) -> 178392 | G11: 178392 | H11: =F11-G11 -> 0 | J11: - | K11: FINALIZADO
B12: Phase Out para Montana | C12: 27213-0 | D12: MONANGE DES ANTI INVISIVEL 12X200ML | F12: =VLOOKUP(C12,'[4]Phase out '!$A:$G,7,0) -> 67423 | H12: =F12-G12 -> 67423 | I12: 67428 | J12: 46182
C13: 27170-0 | D13: ADIDAS DES ANTI POWER BOOSTER FEM 150ML | F13: 234844 | I13: 234072 | J13: 46185 | K13: Fragrância 465405 chega 02/06
B14: Tubo 465344 com vencimento em 08/26 | C14: 27172-0 | D14: ADIDAS DES ANTI POWER BOOSTER MASC 150ML | E14: 17133 | I14: 89196 | J14: 46184
B15: Esgotamento tubo 468239 | C15: 29028-0 | D15: ADIDAS DES ANTI CLINICAL DRY MASC 150ML | E15: 123876 | F15: 0 | H15: 123876 | J15: Julho | K15: Tubo novo: 469926
B16: Esgotamento tubo 468240 | C16: 29029-0 | D16: ADIDAS DES ANTI CLINICAL FRESH MAS 150ML | E16: 112219 | F16: 0 | H16: 112219 | J16: Julho | K16: Tubo novo: 469927
B17: Esgotamento 468506 (TUBO - AGORA) e 467709 (TAMPA - POSTERIORMENTE) | C17: 29140-0 | D17: ADIDAS DES ANTI UEFA GOAL 150ML 12UN | F17: 0 | J17: Julho
B18: PHASE OUT REVAMP | C18: 27171-0 | D18: ADIDAS DES ANTI FRESH ENDURANCE FEM 12X90G | E18: 168896 | J18: PROGRAMAR JUNHO | K18: Fragrância 465410 chega 02/06 - Vou verificar a inserção dele na prog | L18: =_xlfn.XLOOKUP(C18,Planilha1!A:A,Planilha1!G:G,0,0,1) -> 169896 | M18: =_xlfn.XLOOKUP(C18,Planilha1!A:A,Planilha1!F:F,0,0,1) -> Sem data definida

Sheet P&D
A1: Cód. PA | B1: Descrição | C1: Cód. SA | D1: Status | E1: Fabricação | F1: Envase | I1: Material | J1: Texto Produto Acabado | K1: Datas previstas | L1: Qtd (CX) | O1: Material | P1: Texto Produto Acabado | Q1: Categoria / Marca | R1: VERP - Tubo | S1: Tubo | T1: VERP - Tampa | U1: Tampa | V1: ROH | W1: Fragrância | X1: VERP - Válvula | Y1: Válvula | Z1: Autonomia | AA1: SIM
A2: 25643-2 | B2: MONANGE CLIN REVIGORANTE AERO 12X94G MT | C2: 469964 | D2: PLANNED | E2: 28/04 | F2: 29/04 | I2: 27170-0 | J2: ADIDAS DES ANTI POWER BOOSTER FEM 150ML | K2: 46168 | L2: 21237 | O2: 20003-5 | P2: ADIDAS DES AE C&C CONTROL FE AP12X150 NF | Q2: ADIDAS | R2: 460954 | S2: Não | T2: 451922 | U2: Não | W2: Não | X2: 451507 | Y2: Não | Z2: =IF(AND(S2="Sim",U2="Sim",W2="Sim"),"Sim","Não") -> Não | AA2: =COUNTIF(S2:Z2,"Sim") -> 0
A3: 24630-2 | B3: MONANGE DES ANTIT DETOX FRESH 12X90G MT | C3: 469965 | D3: PLANNED | E3: 28/04 a 01/05 | F3: 29/04 a 04/05 | I3: 27172-0 | J3: ADIDAS DES ANTI POWER BOOSTER MASC 150ML | K3: 46171 | L3: 7433 | O3: 20006-5 | P3: ADIDAS DES AE C&C FRESH FE AP 12X150 NF | Q3: ADIDAS | R3: 460955 | S3: Não | T3: 451922 | U3: Não | W3: Não | X3: 451507 | Y3: Não | Z3: =IF(AND(S3="Sim",U3="Sim",W3="Sim"),"Sim","Não") -> Não | AA3: =COUNTIF(S3:Z3,"Sim") -> 0
A4: 25503-1 | B4: MONANGE DES ANTIT ESPORTE AERO 12X90G MT | C4: 469966 | D4: PLANNED | E4: 01/07 | F4: 01/07 | I4: 29140-0 | J4: ADIDAS DES ANTI UEFA GOAL 150ML 12UN | K4: 46170 | L4: 7079 | O4: 20019-3 | P4: ADIDAS DES AE C&C DRYPOWER M AP 12X150SI | Q4: ADIDAS | R4: 456067 | S4: Não | T4: 452006 | W4: Não | X4: 451507 | Y4: Não | Z4: =IF(AND(S4="Sim",U4="Sim",W4="Sim"),"Sim","Não") -> Não | AA4: =COUNTIF(S4:Z4,"Sim") -> 0
A5: 29556-1 | B5: MONANGE DES ANTIT FLOR LAVAN 12X200ML MT | C5: 469967 | D5: PLANNED | E5: 01/07 | F5: 01/07 | I5: 29030-0 | J5: ADIDAS DES ANTI CLINICAL CARE FEM 150ML | K5: 46174 | L5: 4244 | O5: 20125-0 | P5: ADIDAS DES AER CLIMACOOL MAS AP 12X150ML | Q5: ADIDAS | R5: 456070 | S5: Não | T5: 452006 | W5: Não | X5: 451507 | Y5: Não | Z5: =IF(AND(S5="Sim",U5="Sim",W5="Sim"),"Sim","Não") -> Não | AA5: =COUNTIF(S5:Z5,"Sim") -> 0
A6: 27212-1 | B6: MONANGE DES ANTIT FR VERMELH 12X200ML MT | C6: 469968 | D6: PLANNED | E6: 26/05 | F6: 27/05 | I6: Total programado | L6: =SUM(L2:L5) -> 39993 | O6: 20266-0 | P6: ADIDAS DES AERO ADIPOWER FEM AP 150ML | Q6: ADIDAS | R6: 452609 | S6: Não | T6: 451922 | U6: Não | W6: Não | X6: 451507 | Y6: Não | Z6: =IF(AND(S6="Sim",U6="Sim",W6="Sim"),"Sim","Não") -> Não | AA6: =COUNTIF(S6:Z6,"Sim") -> 0
A7: 27211-1 | B7: MONANGE DES ANTIT HID INTENS 12X200ML MT | C7: 469969 | D7: PLANNED | E7: 30/04 a 07/05 | F7: 01/05 a 08/05 | I7: A programar (considerando estoque externo = 79.912 un) | L7: =79916-L6 -> 39923 | O7: 20267-0 | P7: ADIDAS DES AERO ADIPOWER MAS AP 150ML | Q7: ADIDAS | R7: 452610 | S7: Não | T7: 452006 | W7: Não | X7: 451507 | Y7: Não | Z7: =IF(AND(S7="Sim",U7="Sim",W7="Sim"),"Sim","Não") -> Não | AA7: =COUNTIF(S7:Z7,"Sim") -> 0
A8: 27213-1 | B8: MONANGE DES ANTIT INVISIVEL 12X200ML MT | C8: 469970 | D8: PLANNED | E8: 21/05 a 26/05 | F8: 22/05 a 27/05 | O8: 23208-0 | P8: ADIDAS DES AERO INVISIBLE FEM AP 150ML | Q8: ADIDAS | R8: 456775 | S8: Não | T8: 451922 | U8: Não | W8: Não | X8: 451507 | Y8: Não | Z8: =IF(AND(S8="Sim",U8="Sim",W8="Sim"),"Sim","Não") -> Não | AA8: =COUNTIF(S8:Z8,"Sim") -> 0
A9: 29555-1 | B9: MONANGE DES ANTIT PROT SECA 12X200ML MT | C9: 469971 | D9: PLANNED | E9: 28/05 | F9: 29/05 | O9: 23209-2 | P9: ADIDAS DES AE INVISIBLE MAS AP 12X150 NF | Q9: ADIDAS | R9: 460956 | S9: Não | T9: 452006 | W9: Não | X9: 451507 | Y9: Não | Z9: =IF(AND(S9="Sim",U9="Sim",W9="Sim"),"Sim","Não") -> Não | AA9: =COUNTIF(S9:Z9,"Sim") -> 0
O10: 20020-3 | P10: ADIDAS DES AE C&C SPORTENER M AP12X150SI | Q10: ADIDAS | R10: 452899 | S10: Não | T10: 452006 | W10: Não | X10: 451507 | Y10: Não | Z10: =IF(AND(S10="Sim",U10="Sim",W10="Sim"),"Sim","Não") -> Não | AA10: =COUNTIF(S10:Z10,"Sim") -> 0
