Workbook

Sheet Lineares
A2: Linha 22 - LOÇÃO PÓS BARBA | R2: =A2 -> Linha 22 - LOÇÃO PÓS BARBA
A3: LINHA | B3: ORDEM | C3: Lote SA | D3: QTD (KG) | E3: PROGRAMADO | F3: REALIZADO | G3: CÓDIGO | H3: DESCRIÇÃO S.A | I3: DATA CONGELADA | J3: DATA ATUALIZADA | K3: TB | L3: TC | M3: TA | N3: DATA SAP | O3: STATUS | R3: CÓDIGO | S3: DESCRIÇÃO P.A | T3: ORDEM | U3: QTD (CX/UND) | V3: REALIZADO | W3: QTD (CX) | X3: QTD SAP | Y3: DATA SAP | Z3: UNIDADES
J4: 46143 | AE4: =VLOOKUP(B4,COHVPI!A:N,14,0) -> #N/A | AH4: =VLOOKUP(B4,COHVPI!A:E,5,0) -> #N/A | AI4: =AH4-D4 -> #N/A
AE5: =VLOOKUP(B5,COHVPI!A:N,14,0) -> #N/A | AH5: =VLOOKUP(B5,COHVPI!A:E,5,0) -> #N/A | AI5: =AH5-D5 -> #N/A
A6: Linha 23 - BÁLSAMO / GEL PÓS BARBA | R6: =A6 -> Linha 23 - BÁLSAMO / GEL PÓS BARBA | AE6: =VLOOKUP(B6,COHVPI!A:N,14,0) -> #N/A | AH6: =VLOOKUP(B6,COHVPI!A:E,5,0) -> #N/A | AI6: =AH6-D6 -> #N/A
A7: LINHA | B7: ORDEM | C7: Lote SA | D7: QTD (KG) | E7: PROGRAMADO | F7: REALIZADO | G7: CÓDIGO | H7: DESCRIÇÃO S.A | I7: DATA CONGELADA | J7: DATA ATUALIZADA | K7: TB | L7: TC | M7: TA | N7: DATA SAP | O7: STATUS | R7: CÓDIGO | S7: DESCRIÇÃO P.A | T7: ORDEM | U7: QTD (CX/UND) | V7: REALIZADO | W7: QTD (CX) | X7: QTD SAP | Y7: DATA SAP | Z7: UNIDADES | AE7: =VLOOKUP(B7,COHVPI!A:N,14,0) -> Status do sistema | AH7: =VLOOKUP(B7,COHVPI!A:E,5,0) -> Quantidade da ordem (GMEIN) | AI7: =AH7-D7 -> #VALUE!
J8: 46147 | AE8: =VLOOKUP(B8,COHVPI!A:N,14,0) -> #N/A | AH8: =VLOOKUP(B8,COHVPI!A:E,5,0) -> #N/A | AI8: =AH8-D8 -> #N/A
AE9: =VLOOKUP(B9,COHVPI!A:N,14,0) -> #N/A | AH9: =VLOOKUP(B9,COHVPI!A:E,5,0) -> #N/A | AI9: =AH9-D9 -> #N/A
A10: Linha 24 - C&B / CPP | R10: =A10 -> Linha 24 - C&B / CPP | AE10: =VLOOKUP(B10,COHVPI!A:N,14,0) -> #N/A | AH10: =VLOOKUP(B10,COHVPI!A:E,5,0) -> #N/A | AI10: =AH10-D10 -> #N/A
A11: LINHA | B11: ORDEM | C11: Lote SA | D11: QTD (KG) | E11: PROGRAMADO | F11: REALIZADO | G11: CÓDIGO | H11: DESCRIÇÃO S.A | I11: DATA CONGELADA | J11: DATA ATUALIZADA | K11: TB | L11: TC | M11: TA | N11: DATA SAP | O11: STATUS | R11: CÓDIGO | S11: DESCRIÇÃO P.A | T11: ORDEM | U11: QTD (CX/UND) | V11: REALIZADO | W11: QTD (CX) | X11: QTD SAP | Y11: DATA SAP | Z11: UNIDADES | AE11: =VLOOKUP(B11,COHVPI!A:N,14,0) -> Status do sistema | AH11: =VLOOKUP(B11,COHVPI!A:E,5,0) -> Quantidade da ordem (GMEIN) | AI11: =AH11-D11 -> #VALUE!
A12: 24 | B12: 1965365 | C12: T26F0058 | D12: 4000 | G12: 426837 | H12: SA C&B OLEO BRONZEADOR FPS6 | J12: 10/06 A 11/06 | O12: TESTE USANDO O REATOR 1300 | R12: 27538-0 | S12: C&B OLEO BRONZ SPR FPS6 12X110ML OMK | T12: 1965363 | U12: =Z12/12 -> 3389 | Z12: 40668 | AE12: =VLOOKUP(B12,COHVPI!A:N,14,0) -> LIB IMPR CNPA FORN CAPC CPRE LOAT MOME* | AH12: =VLOOKUP(B12,COHVPI!A:E,5,0) -> 4000 | AI12: =AH12-D12 -> 0
J13: 46155 | AE13: =VLOOKUP(B13,COHVPI!A:N,14,0) -> #N/A | AH13: =VLOOKUP(B13,COHVPI!A:E,5,0) -> #N/A | AI13: =AH13-D13 -> #N/A
AE14: =VLOOKUP(B14,COHVPI!A:N,14,0) -> #N/A | AH14: =VLOOKUP(B14,COHVPI!A:E,5,0) -> #N/A | AI14: =AH14-D14 -> #N/A
A15: Linha 26 - SOLUÇÃO PARA CREME DE BARBEAR | AE15: =VLOOKUP(B15,COHVPI!A:N,14,0) -> #N/A | AH15: =VLOOKUP(B15,COHVPI!A:E,5,0) -> #N/A | AI15: =AH15-D15 -> #N/A
A16: LINHA | B16: ORDEM | C16: Lote SA | D16: QTD (KG) | E16: PROGRAMADO | F16: REALIZADO | G16: CÓDIGO | H16: DESCRIÇÃO S.A | I16: DATA CONGELADA | J16: DATA ATUALIZADA | K16: TB | L16: TC | M16: TA | N16: DATA SAP | O16: STATUS | AE16: =VLOOKUP(B16,COHVPI!A:N,14,0) -> Status do sistema | AH16: =VLOOKUP(B16,COHVPI!A:E,5,0) -> Quantidade da ordem (GMEIN) | AI16: =AH16-D16 -> #VALUE!
A17: SOLUÇÃO HIDROXIDO SODIO 36% | AE17: =VLOOKUP(B17,COHVPI!A:N,14,0) -> #N/A | AH17: =VLOOKUP(B17,COHVPI!A:E,5,0) -> #N/A | AI17: =AH17-D17 -> #N/A
A18: 26 | B18: 1963990 | C18: T26E1178 | D18: 9 | E18: =_xlfn.XLOOKUP(B18,COHVPI!A:A,COHVPI!E:E,0,0,1) -> 0 | F18: =_xlfn.XLOOKUP(B18,COHVPI!A:A,COHVPI!F:F) -> #N/A | G18: 414180 | H18: SA SOLUCAO HIDROXIDO SODIO 36% | I18: - | J18: - | N18: =_xlfn.XLOOKUP(B18,COHVPI!A:A,COHVPI!I:I) -> #N/A | O18: - | AE18: =VLOOKUP(B18,COHVPI!A:N,14,0) -> #N/A | AH18: =VLOOKUP(B18,COHVPI!A:E,5,0) -> #N/A | AI18: =AH18-D18 -> #N/A
A19: 26 | B19: 1963991 | C19: T26E1179 | D19: 9 | E19: =_xlfn.XLOOKUP(B19,COHVPI!A:A,COHVPI!E:E,0,0,1) -> 9 | F19: =_xlfn.XLOOKUP(B19,COHVPI!A:A,COHVPI!F:F) -> 9 | G19: 414180 | H19: SA SOLUCAO HIDROXIDO SODIO 36% | I19: - | J19: - | N19: =_xlfn.XLOOKUP(B19,COHVPI!A:A,COHVPI!I:I) -> 46182 | O19: - | AE19: =VLOOKUP(B19,COHVPI!A:N,14,0) -> LIB IMPR CNPA FORN CAPC CPRE DMNV LOAT* | AH19: =VLOOKUP(B19,COHVPI!A:E,5,0) -> 9 | AI19: =AH19-D19 -> 0
A20: 26 | B20: 1963992 | C20: T26E1180 | D20: 9 | E20: =_xlfn.XLOOKUP(B20,COHVPI!A:A,COHVPI!E:E,0,0,1) -> 9 | F20: =_xlfn.XLOOKUP(B20,COHVPI!A:A,COHVPI!F:F) -> 0 | G20: 414180 | H20: SA SOLUCAO HIDROXIDO SODIO 36% | I20: - | J20: - | N20: =_xlfn.XLOOKUP(B20,COHVPI!A:A,COHVPI!I:I) -> 46182 | O20: - | AE20: =VLOOKUP(B20,COHVPI!A:N,14,0) -> LIB IMPR CAPC CPRE DMNV LOAT MOME NOLQ* | AH20: =VLOOKUP(B20,COHVPI!A:E,5,0) -> 9 | AI20: =AH20-D20 -> 0
AE21: =VLOOKUP(B21,COHVPI!A:N,14,0) -> #N/A | AH21: =VLOOKUP(B21,COHVPI!A:E,5,0) -> #N/A | AI21: =AH21-D21 -> #N/A
AE22: =VLOOKUP(B22,COHVPI!A:N,14,0) -> #N/A | AH22: =VLOOKUP(B22,COHVPI!A:E,5,0) -> #N/A | AI22: =AH22-D22 -> #N/A
A23: SOLUÇÃO HIDROXIDO POTASSIO 37% | AE23: =VLOOKUP(B23,COHVPI!A:N,14,0) -> #N/A | AH23: =VLOOKUP(B23,COHVPI!A:E,5,0) -> #N/A | AI23: =AH23-D23 -> #N/A
A24: 26 | B24: 1963973 | C24: T26E1161 | D24: 440 | E24: =_xlfn.XLOOKUP(A24,COHVPI!#REF!,COHVPI!E:E) -> #REF! | F24: =_xlfn.XLOOKUP(B24,COHVPI!A:A,COHVPI!F:F) -> #N/A | G24: 414179 | H24: SA SOLUCAO HIDROXIDO POTASSIO 37% | I24: - | J24: - | N24: =_xlfn.XLOOKUP(B24,COHVPI!A:A,COHVPI!I:I) -> #N/A | O24: - | AE24: =VLOOKUP(B24,COHVPI!A:N,14,0) -> #N/A | AH24: =VLOOKUP(B24,COHVPI!A:E,5,0) -> #N/A | AI24: =AH24-D24 -> #N/A
A25: 26 | B25: 1963974 | C25: T26E1162 | D25: 440 | E25: =_xlfn.XLOOKUP(A25,COHVPI!#REF!,COHVPI!E:E) -> #REF! | F25: =_xlfn.XLOOKUP(B25,COHVPI!A:A,COHVPI!F:F) -> 440 | G25: 414179 | H25: SA SOLUCAO HIDROXIDO POTASSIO 37% | I25: - | J25: - | N25: =_xlfn.XLOOKUP(B25,COHVPI!A:A,COHVPI!I:I) -> 46182 | O25: - | AE25: =VLOOKUP(B25,COHVPI!A:N,14,0) -> LIB IMPR CNPA FORN CAPC CPRE DMNV LOAT* | AH25: =VLOOKUP(B25,COHVPI!A:E,5,0) -> 440 | AI25: =AH25-D25 -> 0
A26: 26 | B26: 1963975 | C26: T26E1163 | D26: 440 | E26: =_xlfn.XLOOKUP(A26,COHVPI!#REF!,COHVPI!E:E) -> #REF! | F26: =_xlfn.XLOOKUP(B26,COHVPI!A:A,COHVPI!F:F) -> 0 | G26: 414179 | H26: SA SOLUCAO HIDROXIDO POTASSIO 37% | I26: - | J26: - | N26: =_xlfn.XLOOKUP(B26,COHVPI!A:A,COHVPI!I:I) -> 46182 | O26: - | AE26: =VLOOKUP(B26,COHVPI!A:N,14,0) -> LIB IMPR CAPC CPRE DMNV LOAT MOME NOLQ* | AH26: =VLOOKUP(B26,COHVPI!A:E,5,0) -> 440 | AI26: =AH26-D26 -> 0
AE27: =VLOOKUP(B27,COHVPI!A:N,14,0) -> #N/A | AH27: =VLOOKUP(B27,COHVPI!A:E,5,0) -> #N/A | AI27: =AH27-D27 -> #N/A
AE28: =VLOOKUP(B28,COHVPI!A:N,14,0) -> #N/A | AH28: =VLOOKUP(B28,COHVPI!A:E,5,0) -> #N/A | AI28: =AH28-D28 -> #N/A
A29: Linha 26 - CREME DE BARBEAR | R29: =A29 -> Linha 26 - CREME DE BARBEAR | AE29: =VLOOKUP(B29,COHVPI!A:N,14,0) -> #N/A | AH29: =VLOOKUP(B29,COHVPI!A:E,5,0) -> #N/A | AI29: =AH29-D29 -> #N/A
A30: LINHA | B30: ORDEM | C30: Lote SA | D30: QTD (KG) | E30: PROGRAMADO | F30: REALIZADO | G30: CÓDIGO | H30: DESCRIÇÃO S.A | I30: DATA CONGELADA | J30: DATA ATUALIZADA | K30: TB | L30: TC | M30: TA | N30: DATA SAP | O30: STATUS | R30: CÓDIGO | S30: DESCRIÇÃO P.A | T30: ORDEM | U30: QTD (CX) | V30: REALIZADO | W30: QTD (CX) | X30: QTD SAP | Y30: DATA SAP | Z30: QTD (UN) | AE30: =VLOOKUP(B30,COHVPI!A:N,14,0) -> Status do sistema | AH30: =VLOOKUP(B30,COHVPI!A:E,5,0) -> Quantidade da ordem (GMEIN) | AI30: =AH30-D30 -> #VALUE!
A31: 26 | B31: 1963963 | C31: T26E1155 | D31: 2300 | G31: 465764 | H31: SA BOZZANO CR BARB PELE SENS COMF REP V1 | I31: 46182 | J31: 46182 | O31: - | R31: 8490-5 | S31: BOZZANO CR BARBEAR PELE SENS 24X65G | T31: 1963925 | U31: =Z31/24 -> 1452 | V31: =_xlfn.XLOOKUP(T31,COHVPI!A:A,COHVPI!F:F) -> #N/A | W31: =Z31/24 -> 1452 | Y31: =_xlfn.XLOOKUP(Q31,COHVPI!#REF!,COHVPI!F:F) -> #REF! | Z31: 34848 | AE31: =VLOOKUP(B31,COHVPI!A:N,14,0) -> #N/A | AH31: =VLOOKUP(B31,COHVPI!A:E,5,0) -> #N/A | AI31: =AH31-D31 -> #N/A
A32: 26 | B32: 1963964 | C32: T26E1156 | D32: 2300 | G32: 465764 | H32: SA BOZZANO CR BARB PELE SENS COMF REP V1 | I32: 46182 | J32: 09/06 A 11/06 | O32: - | R32: 8490-5 | S32: BOZZANO CR BARBEAR PELE SENS 24X65G | T32: 1963926 | U32: =Z32/24 -> 1452 | V32: =_xlfn.XLOOKUP(T32,COHVPI!A:A,COHVPI!F:F) -> #N/A | W32: =Z32/24 -> 1452 | Y32: =_xlfn.XLOOKUP(Q32,COHVPI!#REF!,COHVPI!F:F) -> #REF! | Z32: 34848 | AE32: =VLOOKUP(B32,COHVPI!A:N,14,0) -> #N/A | AH32: =VLOOKUP(B32,COHVPI!A:E,5,0) -> #N/A | AI32: =AH32-D32 -> #N/A
A33: 26 | B33: 1963965 | C33: T26E1157 | D33: 2300 | G33: 465764 | H33: SA BOZZANO CR BARB PELE SENS COMF REP V1 | J33: 11/06 A 13/06 | O33: - | R33: 8490-5 | S33: BOZZANO CR BARBEAR PELE SENS 24X65G | T33: 1963928 | U33: =Z33/24 -> 1452 | V33: =_xlfn.XLOOKUP(T33,COHVPI!A:A,COHVPI!F:F) -> #N/A | W33: =Z33/24 -> 1452 | Y33: =_xlfn.XLOOKUP(Q33,COHVPI!#REF!,COHVPI!F:F) -> #REF! | Z33: 34848 | AE33: =VLOOKUP(B33,COHVPI!A:N,14,0) -> #N/A | AH33: =VLOOKUP(B33,COHVPI!A:E,5,0) -> #N/A | AI33: =AH33-D33 -> #N/A
AE34: =VLOOKUP(B34,COHVPI!A:N,14,0) -> #N/A | AH34: =VLOOKUP(B34,COHVPI!A:E,5,0) -> #N/A | AI34: =AH34-D34 -> #N/A
AE35: =VLOOKUP(B35,COHVPI!A:N,14,0) -> #N/A | AH35: =VLOOKUP(B35,COHVPI!A:E,5,0) -> #N/A | AI35: =AH35-D35 -> #N/A
A36: Linha 27 - BISNAGAS | R36: =A36 -> Linha 27 - BISNAGAS | AE36: =VLOOKUP(B36,COHVPI!A:N,14,0) -> #N/A | AH36: =VLOOKUP(B36,COHVPI!A:E,5,0) -> #N/A | AI36: =AH36-D36 -> #N/A
A37: LINHA | B37: ORDEM | C37: Lote SA | D37: QTD (KG) | E37: PROGRAMADO | F37: REALIZADO | G37: CÓDIGO | H37: DESCRIÇÃO S.A | I37: DATA CONGELADA | J37: DATA ATUALIZADA | K37: TB | L37: TC | M37: TA | N37: DATA SAP | O37: STATUS | R37: CÓDIGO | S37: DESCRIÇÃO P.A | T37: ORDEM | U37: QTD (CX) | V37: REALIZADO | W37: QTD (CX) | X37: QTD SAP | Y37: DATA SAP | Z37: QTD (UN) | AE37: =VLOOKUP(B37,COHVPI!A:N,14,0) -> Status do sistema | AH37: =VLOOKUP(B37,COHVPI!A:E,5,0) -> Quantidade da ordem (GMEIN) | AI37: =AH37-D37 -> #VALUE!
A38: 27 | B38: 1963909 | C38: T26E1132 | D38: 6000 | G38: 468177 | H38: SA MONANGE GEL LIMPEZA FACIAL PL SECA | I38: 46177 | J38: 04/06 A 08/06 | O38: - | R38: 26821-1 | S38: MONANGE FAC GEL LIMP GELTIL 6X120G CR | T38: 1963908 | U38: =Z38/6 -> 8333 | V38: =_xlfn.XLOOKUP(T38,COHVPI!A:A,COHVPI!F:F) -> 5880 | W38: =Z38/6 -> 8333 | Y38: =_xlfn.XLOOKUP(Q38,COHVPI!#REF!,COHVPI!F:F) -> #REF! | Z38: 49998 | AE38: =VLOOKUP(B38,COHVPI!A:N,14,0) -> #N/A | AH38: =VLOOKUP(B38,COHVPI!A:E,5,0) -> #N/A | AI38: =AH38-D38 -> #N/A
H39: MOD PARA A L24 | S39: MOD PARA A L24 | V39: =_xlfn.XLOOKUP(T39,COHVPI!A:A,COHVPI!F:F) -> 0 | AD39: =VLOOKUP(B39,[1]COHVPI!A:N,14,0) -> #N/A | AE39: =VLOOKUP(B39,COHVPI!A:N,14,0) -> #N/A | AH39: =VLOOKUP(B39,COHVPI!A:E,5,0) -> #N/A | AI39: =AH39-D39 -> #N/A | AJ39: =AI39-#REF! -> #N/A
AE40: =VLOOKUP(B40,COHVPI!A:N,14,0) -> #N/A | AH40: =VLOOKUP(B40,COHVPI!A:E,5,0) -> #N/A | AI40: =AH40-D40 -> #N/A
AE41: =VLOOKUP(B41,COHVPI!A:N,14,0) -> #N/A | AH41: =VLOOKUP(B41,COHVPI!A:E,5,0) -> #N/A | AI41: =AH41-D41 -> #N/A
...

Sheet Aderência Diária

Sheet COHVPI
A1: Ordem | B1: Nº do material | C1: Texto breve de material | D1: Lote | E1: Quantidade da ordem (GMEIN) | F1: Qtd.fornecida (GMEIN) | G1: Unidade de medida (=GMEIN) | H1: Planejador MRP | I1: Data-base iníc. | J1: Data de conclusão base | K1: Hr.início programada | L1: Fim program. (hora) | M1: Versão de produção | N1: Status do sistema
A2: 1964323 | B2: 10992-2 | C2: AVANCO DES SPRAY ACTION 12X85ML NVE | E2: 4731 | F2: 0 | G2: CX | H2: Z03 | I2: 46198 | J2: 46198 | K2: 0.27777778 | L2: 0.6490162 | N2: ABER CNAT DMNV NOLQ ORSL
A3: 1964123 | B3: 15476-3 | C3: PAIXAO DEO LOCAO IRRES FLOR LIS 24X200ML | E3: 7830 | F3: 0 | G3: CX | H3: Z03 | I3: 46200 | J3: 46202 | K3: 0.27777778 | L3: 0.3474537 | N3: ABER CNAT DMNV NOLQ ORSL
A4: 1964124 | B4: 15476-3 | C4: PAIXAO DEO LOCAO IRRES FLOR LIS 24X200ML | E4: 7830 | F4: 0 | G4: CX | H4: Z03 | I4: 46203 | J4: 46204 | K4: 0.27777778 | L4: 0.3474537 | N4: ABER CNAT DMNV NOLQ ORSL
A5: 1964116 | B5: 15479-3 | C5: PAIXAO DEO LOCAO TENT AMEIXA RU 24X200ML | E5: 7830 | F5: 0 | G5: CX | H5: Z03 | I5: 46192 | J5: 46193 | K5: 0.27777778 | L5: 0.3474537 | N5: ABER CNAT DMNV NOLQ ORSL
A6: 1964117 | B6: 15479-3 | C6: PAIXAO DEO LOCAO TENT AMEIXA RU 24X200ML | E6: 7830 | F6: 0 | G6: CX | H6: Z03 | I6: 46193 | J6: 46195 | K6: 0.27777778 | L6: 0.3474537 | N6: ABER CNAT DMNV NOLQ ORSL
A7: 1964331 | B7: 15492-3 | C7: PAIXAO DEO OLEO INSP ROSAS BRAN 12X200ML | E7: 8232 | F7: 0 | G7: CX | H7: Z03 | I7: 46191 | J7: 46192 | K7: 0.27777778 | L7: 0.15726852 | N7: ABER CNAT DMNV NOLQ ORSL
A8: 1964492 | B8: 15496-3 | C8: PAIXAO DEO OLEO TENT AMEIXA RUB 12X200ML | E8: 8232 | F8: 0 | G8: CX | H8: Z03 | I8: 46192 | J8: 46193 | K8: 0.27777778 | L8: 0.15726852 | N8: ABER CNAT DMNV NOLQ ORSL
A9: 1961374 | B9: 17063-1 | C9: CONTOURE DES VOLPI SPR AMOR VIDA 12X80ML | E9: 5275 | F9: 0 | G9: CX | H9: Z03 | I9: 46193 | J9: 46193 | K9: 0.27777778 | L9: 0.69170139 | N9: ABER CNAT DMNV NOLQ ORSL
A10: 1961373 | B10: 17064-1 | C10: CONTOURE DES VOLPI SPR PRIM AMOR 12X80ML | E10: 5275 | F10: 0 | G10: CX | H10: Z03 | I10: 46183 | J10: 46183 | K10: 0.27777778 | L10: 0.69170139 | N10: ABER CNAT DMNV NOLQ ORSL
A11: 1964306 | B11: 17065-1 | C11: CONTOURE DES VOLPI SPR LEMBRANCA 12X80ML | E11: 5275 | F11: 0 | G11: CX | H11: Z03 | I11: 46195 | J11: 46195 | K11: 0.27777778 | L11: 0.69170139 | N11: ABER CNAT DMNV NOLQ ORSL
A12: 1964235 | B12: 17284-5 | C12: MONANGE DEO CORP HIDR AVEIA 24X200ML PT | E12: 7996 | F12: 0 | G12: CX | H12: Z03 | I12: 46193 | J12: 46195 | K12: 0.27777778 | L12: 0.70083333 | N12: ABER CNAT DMNV NOLQ ORSL
A13: 1964236 | B13: 17284-5 | C13: MONANGE DEO CORP HIDR AVEIA 24X200ML PT | E13: 7996 | F13: 0 | G13: CX | H13: Z03 | I13: 46195 | J13: 46196 | K13: 0.27777778 | L13: 0.70083333 | N13: ABER CNAT DMNV NOLQ ORSL
... A17: 1964225 | B17: 17874-7 | C17: MONANGE DES CORP HIDR PL EXT 12X400ML PT | E17: 7916 | F17: 0 | G17: CX | H17: Z03 | I17: 46184 | J17: 46185 | K17: 0.27777778 | L17: 0.51159722 | N17: ABER CNAT DMNV NOLQ ORSL
A18: 1961445 | B18: 18000-4 | C18: PAIXAO DEO LOCAO IRRES FLOR LIS 12X400ML | D18: 6155C1 | E18: 7806 | F18: 7094 | G18: CX | H18: Z03 | I18: 46178 | J18: 46179 | K18: 0.27777778 | L18: 0.27854167 | N18: LIB MATF IMPR CNPA CAPC CPRE FRNP LOAT*
A19: 1961459 | B19: 20462-1 | C19: PAIXAO DEO OLEO AVELA 24X100ML | D19: 6153C1 | E19: 4116 | F19: 4249 | G19: CX | H19: Z03 | I19: 46175 | J19: 46177 | K19: 0.58484954 | L19: 0.49967593 | N19: LIB IMPR CNPA FORN CAPC CPRE DMNV LOAT*
A20: 1964317 | B20: 20462-1 | C20: PAIXAO DEO OLEO AVELA 24X100ML | E20: 4116 | F20: 0 | G20: CX | H20: Z03 | I20: 46182 | J20: 46183 | K20: 0.27777778 | L20: 0.24126157 | N20: ABER CNAT DMNV NOLQ ORSL
A21: 1964320 | B21: 20462-1 | C21: PAIXAO DEO OLEO AVELA 24X100ML | E21: 4116 | F21: 0 | G21: CX | H21: Z03 | I21: 46183 | J21: 46184 | K21: 0.27777778 | L21: 0.24126157 | N21: ABER CNAT DMNV NOLQ ORSL
A22: 1965391 | B22: 20462-1 | C22: PAIXAO DEO OLEO AVELA 24X100ML | E22: 4200 | F22: 0 | G22: CX | H22: Z03 | I22: 46203 | J22: 46204 | K22: 0.27777778 | L22: 0.26092593 | N22: ABER CNAT DMNV NOLQ ORSL
A23: 1964314 | B23: 20464-1 | C23: PAIXAO DEO OLEO TENT AMEIXA RU 24X100ML | D23: 6159C1 | E23: 4116 | F23: 0 | G23: CX | H23: Z03 | I23: 46178 | J23: 46179 | K23: 0.27777778 | L23: 0.24396991 | N23: LIB MATF IMPR CAPC CPRE LOAT NOLQ ORSL
A24: 1964315 | B24: 20464-1 | C24: PAIXAO DEO OLEO TENT AMEIXA RU 24X100ML | E24: 4116 | F24: 0 | G24: CX | H24: Z03 | I24: 46181 | J24: 46182 | K24: 0.27777778 | L24: 0.24396991 | N24: ABER CNAT DMNV NOLQ ORSL
A25: 1964322 | B25: 20464-1 | C25: PAIXAO DEO OLEO TENT AMEIXA RU 24X100ML | E25: 4116 | F25: 0 | G25: CX | H25: Z03 | I25: 46184 | J25: 46185 | K25: 0.27777778 | L25: 0.24396991 | N25: ABER CNAT DMNV NOLQ ORSL
A26: 1964324 | B26: 20464-1 | C26: PAIXAO DEO OLEO TENT AMEIXA RU 24X100ML | E26: 4116 | F26: 0 | G26: CX | H26: Z03 | I26: 46185 | J26: 46186 | K26: 0.27777778 | L26: 0.24396991 | N26: ABER CNAT DMNV NOLQ ORSL
A27: 1964336 | B27: 20464-1 | C27: PAIXAO DEO OLEO TENT AMEIXA RU 24X100ML | E27: 4116 | F27: 0 | G27: CX | H27: Z03 | I27: 46196 | J27: 46197 | K27: 0.27777778 | L27: 0.24396991 | N27: ABER CNAT DMNV NOLQ ORSL
A28: 1964337 | B28: 20464-1 | C28: PAIXAO DEO OLEO TENT AMEIXA RU 24X100ML | E28: 4116 | F28: 0 | G28: CX | H28: Z03 | I28: 46197 | J28: 46198 | K28: 0.27777778 | L28: 0.24396991 | N28: ABER CNAT DMNV NOLQ ORSL
A29: 1964486 | B29: 23473-1 | C29: BOZZANO GEL COND FAT2 BM 6X300G | D29: 6154C3 | E29: 4927 | F29: 5142 | G29: CX | H29: Z03 | I29: 46177 | J29: 46177 | K29: 0.27777778 | L29: 0.61993056 | N29: LIB MATF IMPR CNPA FORN CAPC CPRE DMNV*
A30: 1964091 | B30: 23484-0 | C30: NYLOOKS GEL COND GAR FAT4 12X240G | D30: 6157C1 | E30: 3054 | F30: 2340 | G30: CX | H30: Z03 | I30: 46181 | J30: 46181 | K30: 0.27777778 | L30: 0.70194444 | N30: LIB IMPR CNPA CAPC CPRE DMNV FRNP LOAT*
A31: 1964092 | B31: 23484-0 | C31: NYLOOKS GEL COND GAR FAT4 12X240G | D31: 6159C1 | E31: 3054 | F31: 0 | G31: CX | H31: Z03 | I31: 46181 | J31: 46181 | K31: 0.27777778 | L31: 0.70194444 | N31: LIB MATF IMPR CAPC CPRE LOAT NOLQ ORSL
A32: 1964093 | B32: 23484-0 | C32: NYLOOKS GEL COND GAR FAT4 12X240G | E32: 3054 | F32: 0 | G32: CX | H32: Z03 | I32: 46182 | J32: 46182 | K32: 0.27777778 | L32: 0.70194444 | N32: ABER CNAT DMNV NOLQ ORSL
A33: 1964094 | B33: 23484-0 | C33: NYLOOKS GEL COND GAR FAT4 12X240G | E33: 3054 | F33: 0 | G33: CX | H33: Z03 | I33: 46182 | J33: 46182 | K33: 0.27777778 | L33: 0.70194444 | N33: ABER CNAT DMNV NOLQ ORSL
A34: 1964095 | B34: 23484-0 | C34: NYLOOKS GEL COND GAR FAT4 12X240G | E34: 3054 | F34: 0 | G34: CX | H34: Z03 | I34: 46183 | J34: 46183 | K34: 0.27777778 | L34: 0.70194444 | N34: ABER CNAT DMNV NOLQ ORSL
A35: 1964488 | B35: 23484-0 | C35: NYLOOKS GEL COND GAR FAT4 12X240G | E35: 3054 | F35: 0 | G35: CX | H35: Z03 | I35: 46184 | J35: 46184 | K35: 0.27777778 | L35: 0.70194444 | N35: ABER CNAT DMNV NOLQ ORSL
A36: 1964491 | B36: 23484-0 | C36: NYLOOKS GEL COND GAR FAT4 12X240G | E36: 3054 | F36: 0 | G36: CX | H36: Z03 | I36: 46184 | J36: 46184 | K36: 0.27777778 | L36: 0.70194444 | N36: ABER CNAT DMNV NOLQ ORSL
A37: 1964489 | B37: 23484-0 | C37: NYLOOKS GEL COND GAR FAT4 12X240G | E37: 3054 | F37: 0 | G37: CX | H37: Z03 | I37: 46185 | J37: 46185 | K37: 0.27777778 | L37: 0.70194444 | N37: ABER CNAT DMNV NOLQ ORSL
A38: 1964490 | B38: 23484-0 | C38: NYLOOKS GEL COND GAR FAT4 12X240G | E38: 3054 | F38: 0 | G38: CX | H38: Z03 | I38: 46185 | J38: 46185 | K38: 0.27777778 | L38: 0.70194444 | N38: ABER CNAT DMNV NOLQ ORSL
A39: 1964060 | B39: 24040-2 | C39: MONANGE SH HIDRATACAO INTENS 12X325ML | E39: 9600 | F39: 0 | G39: CX | H39: Z03 | I39: 46199 | J39: 46200 | K39: 0.27777778 | L39: 0.047013889 | N39: ABER CNAT DMNV NOLQ ORSL
A40: 1964063 | B40: 24040-2 | C40: MONANGE SH HIDRATACAO INTENS 12X325ML | E40: 9600 | F40: 0 | G40: CX | H40: Z03 | I40: 46202 | J40: 46203 | K40: 0.27777778 | L40: 0.047013889 | N40: ABER CNAT DMNV NOLQ ORSL
A41: 1964055 | B41: 24041-2 | C41: MONANGE SH LISOS BRILHANTES 12X325ML | E41: 9600 | F41: 0 | G41: CX | H41: Z03 | I41: 46192 | J41: 46193 | K41: 0.27777778 | L41: 0.047013889 | N41: ABER CNAT DMNV NOLQ ORSL
A42: 1964056 | B42: 24041-2 | C42: MONANGE SH LISOS BRILHANTES 12X325ML | E42: 9600 | F42: 0 | G42: CX | H42: Z03 | I42: 46193 | J42: 46194 | K42: 0.27777778 | L42: 0.047013889 | N42: ABER CNAT DMNV NOLQ ORSL
A43: 1964058 | B43: 24042-2 | C43: MONANGE SH CACHOS DEFINIDOS 12X325ML | E43: 9600 | F43: 0 | G43: CX | H43: Z03 | I43: 46196 | J43: 46197 | K43: 0.27777778 | L43: 0.047013889 | N43: ABER CNAT DMNV NOLQ ORSL
...

Sheet MASTERDATA
A1: CODE | B1: DESCRIPTION | C1: UN | D1: PLANNER | E1: CATEGORY | F1: SALES SUB - CATEGORY | G1: SUB-CATEGORY | H1: LINE PRODUCTION | I1: LINHA RCCP | J1: SAFETY DAYS TOTAL | K1: CONV | L1: PLANO AGOSTO | M1: PRODUZIDO
A2: 10992-2 | B2: AVANCO DES SPRAY ACTION 12X85ML NVE | C2: CX | D2: Z03 | E2: DES SPRAY | F2: DESODORANTE | G2: AVANÇO | H2: L07 - ENV DESODORANTE SPRAY | I2: DESODORANTE_SPRAY | J2: 44 | K2: 12 | L2: 21132
A3: 771-5 | B3: AVANCO DES SPRAY ORIGINAL 12X85ML NVE | C3: CX | D3: Z03 | E3: DES SPRAY | F3: DESODORANTE | G3: AVANÇO | H3: L07 - ENV DESODORANTE SPRAY | I3: DESODORANTE_SPRAY | J3: 44 | K3: 12 | L3: 0
A4: 20279-0 | B4: BITUFO GD COCORICO C/F TUTI FRUTTI 90G | C4: CX | D4: Z08 | E4: CREME/GEL DENTAL | F4: ORAL CARE | G4: TRADICIONAL | H4: L35 - ENV CREME/GEL DENTAL BISN | I4: CD_GD_90G | J4: 15 | K4: 1 | L4: 0
A5: 20277-0 | B5: BITUFO GD COCORICO S/F MORANGO 90G | C5: CX | D5: Z08 | E5: CREME/GEL DENTAL | F5: ORAL CARE | G5: TRADICIONAL | H5: L35 - ENV CREME/GEL DENTAL BISN | I5: CD_GD_90G | J5: 22 | K5: 1 | L5: 0
A6: 20278-0 | B6: BITUFO GD COCORICO S/F TUTI FRUTTI 90G | C6: CX | D6: Z08 | E6: CREME/GEL DENTAL | F6: ORAL CARE | G6: TRADICIONAL | H6: L35 - ENV CREME/GEL DENTAL BISN | I6: CD_GD_90G | J6: 22 | K6: 1 | L6: 0
A7: 16768-5 | B7: BITUFO GD C FLUOR T FRUTI L TUNES 90G DL | C7: CX | D7: Z08 | E7: CREME/GEL DENTAL | F7: ORAL CARE | G7: TRADICIONAL | H7: L35 - ENV CREME/GEL DENTAL BISN | I7: CD_GD_90G | J7: 66 | K7: 1 | L7: 0
A8: 17297-2 | B8: BOZZANO BALSAMO POS HIDRAT 12X100G CIN | C8: CX | D8: Z08 | E8: BARBA BOZZANO | F8: PRÉ/PÓS BARBA | G8: BALSAMO POS BARBA BOZZANO | H8: L23 - ENV MANUAL ROT | I8: BARBA BOZZANO 100G | J8: 15 | K8: 12 | L8: 0
A9: 17298-2 | B9: BOZZANO BALSAMO POS PEL SENS 12X100G CIN | C9: CX | D9: Z08 | E9: BARBA BOZZANO | F9: PRÉ/PÓS BARBA | G9: BALSAMO POS BARBA BOZZANO | H9: L23 - ENV MANUAL ROT | I9: BARBA BOZZANO 100G | J9: 22 | K9: 12 | L9: 0
A10: 17299-2 | B10: BOZZANO GEL POS BARBA REFRES 12X100G CIN | C10: CX | D10: Z08 | E10: BARBA BOZZANO | F10: PRÉ/PÓS BARBA | G10: GEL POS BARBA BOZZANO | H10: L23 - ENV MANUAL ROT | I10: BARBA BOZZANO 100G | J10: 15 | K10: 12 | L10: 0
A11: 23473-1 | B11: BOZZANO GEL COND FAT2 BM 6X300G | C11: CX | D11: Z03 | E11: GEL MODELADOR BOZZANO | F11: MODELADOR DE CABELO | G11: BOZZANO 300G | H11: L08 - ENV GEL BOCA LARGA | I11: GEL_B.LARGA | J11: 44 | K11: 6 | L11: 0
A12: 23474-1 | B12: BOZZANO GEL COND FAT3 PROT SOLAR 6X300G | C12: CX | D12: Z03 | E12: GEL MODELADOR BOZZANO | F12: MODELADOR DE CABELO | G12: BOZZANO 300G | H12: L08 - ENV GEL BOCA LARGA | I12: GEL_B.LARGA | J12: 44 | K12: 6 | L12: 0
A13: 23475-1 | B13: BOZZANO GEL COND FAT4 6X300G | C13: CX | D13: Z03 | E13: GEL MODELADOR BOZZANO | F13: MODELADOR DE CABELO | G13: BOZZANO 300G | H13: L08 - ENV GEL BOCA LARGA | I13: GEL_B.LARGA | J13: 44 | K13: 6 | L13: 109440
... A170: 2475-6 | B170: LEITE COLONIA TOQUE C 24X200ML | C170: CX | D170: Z03 | E170: LEITE DE COLONIA | F170: CORPO | G170: LEITE DE COLONIA | H170: L06 - ENV LEITE COLONIA | I170: LEITE_COLONIA_200 | J170: 44 | K170: 24 | L170: 0
